[2024-02-16T08:46:50.104+0000] {processor.py:161} INFO - Started process (PID=361378) to work on /home/pkn/e-commerce_data_pipeline/dags/etl_dag.py
[2024-02-16T08:46:50.105+0000] {processor.py:830} INFO - Processing file /home/pkn/e-commerce_data_pipeline/dags/etl_dag.py for tasks to queue
[2024-02-16T08:46:50.106+0000] {logging_mixin.py:188} INFO - [2024-02-16T08:46:50.106+0000] {dagbag.py:538} INFO - Filling up the DagBag from /home/pkn/e-commerce_data_pipeline/dags/etl_dag.py
[2024-02-16T08:46:50.118+0000] {logging_mixin.py:188} INFO - [2024-02-16T08:46:50.117+0000] {dagbag.py:348} ERROR - Failed to import: /home/pkn/e-commerce_data_pipeline/dags/etl_dag.py
Traceback (most recent call last):
  File "/home/pkn/e-commerce_data_pipeline/venv/lib/python3.10/site-packages/airflow/models/dagbag.py", line 344, in parse
    loader.exec_module(new_module)
  File "<frozen importlib._bootstrap_external>", line 883, in exec_module
  File "<frozen importlib._bootstrap>", line 241, in _call_with_frames_removed
  File "/home/pkn/e-commerce_data_pipeline/dags/etl_dag.py", line 29, in <module>
    python_callable = clean_transform_main,
NameError: name 'clean_transform_main' is not defined
[2024-02-16T08:46:50.118+0000] {processor.py:842} WARNING - No viable dags retrieved from /home/pkn/e-commerce_data_pipeline/dags/etl_dag.py
[2024-02-16T08:46:50.145+0000] {processor.py:183} INFO - Processing /home/pkn/e-commerce_data_pipeline/dags/etl_dag.py took 0.046 seconds
[2024-02-16T08:47:20.673+0000] {processor.py:161} INFO - Started process (PID=361671) to work on /home/pkn/e-commerce_data_pipeline/dags/etl_dag.py
[2024-02-16T08:47:20.683+0000] {processor.py:830} INFO - Processing file /home/pkn/e-commerce_data_pipeline/dags/etl_dag.py for tasks to queue
[2024-02-16T08:47:20.684+0000] {logging_mixin.py:188} INFO - [2024-02-16T08:47:20.683+0000] {dagbag.py:538} INFO - Filling up the DagBag from /home/pkn/e-commerce_data_pipeline/dags/etl_dag.py
[2024-02-16T08:47:20.691+0000] {logging_mixin.py:188} INFO - [2024-02-16T08:47:20.691+0000] {dagbag.py:348} ERROR - Failed to import: /home/pkn/e-commerce_data_pipeline/dags/etl_dag.py
Traceback (most recent call last):
  File "/home/pkn/e-commerce_data_pipeline/venv/lib/python3.10/site-packages/airflow/models/dagbag.py", line 344, in parse
    loader.exec_module(new_module)
  File "<frozen importlib._bootstrap_external>", line 883, in exec_module
  File "<frozen importlib._bootstrap>", line 241, in _call_with_frames_removed
  File "/home/pkn/e-commerce_data_pipeline/dags/etl_dag.py", line 29, in <module>
    python_callable = clean_transform_main,
NameError: name 'clean_transform_main' is not defined
[2024-02-16T08:47:20.692+0000] {processor.py:842} WARNING - No viable dags retrieved from /home/pkn/e-commerce_data_pipeline/dags/etl_dag.py
[2024-02-16T08:47:20.723+0000] {processor.py:183} INFO - Processing /home/pkn/e-commerce_data_pipeline/dags/etl_dag.py took 0.055 seconds
[2024-02-16T08:47:50.847+0000] {processor.py:161} INFO - Started process (PID=361887) to work on /home/pkn/e-commerce_data_pipeline/dags/etl_dag.py
[2024-02-16T08:47:50.849+0000] {processor.py:830} INFO - Processing file /home/pkn/e-commerce_data_pipeline/dags/etl_dag.py for tasks to queue
[2024-02-16T08:47:50.850+0000] {logging_mixin.py:188} INFO - [2024-02-16T08:47:50.850+0000] {dagbag.py:538} INFO - Filling up the DagBag from /home/pkn/e-commerce_data_pipeline/dags/etl_dag.py
[2024-02-16T08:47:50.857+0000] {logging_mixin.py:188} INFO - [2024-02-16T08:47:50.856+0000] {dagbag.py:348} ERROR - Failed to import: /home/pkn/e-commerce_data_pipeline/dags/etl_dag.py
Traceback (most recent call last):
  File "/home/pkn/e-commerce_data_pipeline/venv/lib/python3.10/site-packages/airflow/models/dagbag.py", line 344, in parse
    loader.exec_module(new_module)
  File "<frozen importlib._bootstrap_external>", line 883, in exec_module
  File "<frozen importlib._bootstrap>", line 241, in _call_with_frames_removed
  File "/home/pkn/e-commerce_data_pipeline/dags/etl_dag.py", line 29, in <module>
    python_callable = clean_transform_main,
NameError: name 'clean_transform_main' is not defined
[2024-02-16T08:47:50.857+0000] {processor.py:842} WARNING - No viable dags retrieved from /home/pkn/e-commerce_data_pipeline/dags/etl_dag.py
[2024-02-16T08:47:50.886+0000] {processor.py:183} INFO - Processing /home/pkn/e-commerce_data_pipeline/dags/etl_dag.py took 0.047 seconds
[2024-02-16T08:48:21.043+0000] {processor.py:161} INFO - Started process (PID=362079) to work on /home/pkn/e-commerce_data_pipeline/dags/etl_dag.py
[2024-02-16T08:48:21.045+0000] {processor.py:830} INFO - Processing file /home/pkn/e-commerce_data_pipeline/dags/etl_dag.py for tasks to queue
[2024-02-16T08:48:21.046+0000] {logging_mixin.py:188} INFO - [2024-02-16T08:48:21.045+0000] {dagbag.py:538} INFO - Filling up the DagBag from /home/pkn/e-commerce_data_pipeline/dags/etl_dag.py
[2024-02-16T08:48:21.052+0000] {logging_mixin.py:188} INFO - [2024-02-16T08:48:21.052+0000] {dagbag.py:348} ERROR - Failed to import: /home/pkn/e-commerce_data_pipeline/dags/etl_dag.py
Traceback (most recent call last):
  File "/home/pkn/e-commerce_data_pipeline/venv/lib/python3.10/site-packages/airflow/models/dagbag.py", line 344, in parse
    loader.exec_module(new_module)
  File "<frozen importlib._bootstrap_external>", line 883, in exec_module
  File "<frozen importlib._bootstrap>", line 241, in _call_with_frames_removed
  File "/home/pkn/e-commerce_data_pipeline/dags/etl_dag.py", line 29, in <module>
    python_callable = clean_transform_main,
NameError: name 'clean_transform_main' is not defined
[2024-02-16T08:48:21.053+0000] {processor.py:842} WARNING - No viable dags retrieved from /home/pkn/e-commerce_data_pipeline/dags/etl_dag.py
[2024-02-16T08:48:21.095+0000] {processor.py:183} INFO - Processing /home/pkn/e-commerce_data_pipeline/dags/etl_dag.py took 0.058 seconds
[2024-02-16T08:48:51.632+0000] {processor.py:161} INFO - Started process (PID=362298) to work on /home/pkn/e-commerce_data_pipeline/dags/etl_dag.py
[2024-02-16T08:48:51.634+0000] {processor.py:830} INFO - Processing file /home/pkn/e-commerce_data_pipeline/dags/etl_dag.py for tasks to queue
[2024-02-16T08:48:51.635+0000] {logging_mixin.py:188} INFO - [2024-02-16T08:48:51.634+0000] {dagbag.py:538} INFO - Filling up the DagBag from /home/pkn/e-commerce_data_pipeline/dags/etl_dag.py
[2024-02-16T08:48:51.642+0000] {logging_mixin.py:188} INFO - [2024-02-16T08:48:51.641+0000] {dagbag.py:348} ERROR - Failed to import: /home/pkn/e-commerce_data_pipeline/dags/etl_dag.py
Traceback (most recent call last):
  File "/home/pkn/e-commerce_data_pipeline/venv/lib/python3.10/site-packages/airflow/models/dagbag.py", line 344, in parse
    loader.exec_module(new_module)
  File "<frozen importlib._bootstrap_external>", line 883, in exec_module
  File "<frozen importlib._bootstrap>", line 241, in _call_with_frames_removed
  File "/home/pkn/e-commerce_data_pipeline/dags/etl_dag.py", line 29, in <module>
    python_callable = clean_transform_main,
NameError: name 'clean_transform_main' is not defined
[2024-02-16T08:48:51.642+0000] {processor.py:842} WARNING - No viable dags retrieved from /home/pkn/e-commerce_data_pipeline/dags/etl_dag.py
[2024-02-16T08:48:51.672+0000] {processor.py:183} INFO - Processing /home/pkn/e-commerce_data_pipeline/dags/etl_dag.py took 0.046 seconds
[2024-02-16T08:49:21.773+0000] {processor.py:161} INFO - Started process (PID=362617) to work on /home/pkn/e-commerce_data_pipeline/dags/etl_dag.py
[2024-02-16T08:49:21.775+0000] {processor.py:830} INFO - Processing file /home/pkn/e-commerce_data_pipeline/dags/etl_dag.py for tasks to queue
[2024-02-16T08:49:21.776+0000] {logging_mixin.py:188} INFO - [2024-02-16T08:49:21.775+0000] {dagbag.py:538} INFO - Filling up the DagBag from /home/pkn/e-commerce_data_pipeline/dags/etl_dag.py
[2024-02-16T08:49:21.781+0000] {logging_mixin.py:188} INFO - [2024-02-16T08:49:21.781+0000] {dagbag.py:348} ERROR - Failed to import: /home/pkn/e-commerce_data_pipeline/dags/etl_dag.py
Traceback (most recent call last):
  File "/home/pkn/e-commerce_data_pipeline/venv/lib/python3.10/site-packages/airflow/models/dagbag.py", line 344, in parse
    loader.exec_module(new_module)
  File "<frozen importlib._bootstrap_external>", line 883, in exec_module
  File "<frozen importlib._bootstrap>", line 241, in _call_with_frames_removed
  File "/home/pkn/e-commerce_data_pipeline/dags/etl_dag.py", line 29, in <module>
    python_callable = clean_transform_main,
NameError: name 'clean_transform_main' is not defined
[2024-02-16T08:49:21.782+0000] {processor.py:842} WARNING - No viable dags retrieved from /home/pkn/e-commerce_data_pipeline/dags/etl_dag.py
[2024-02-16T08:49:21.801+0000] {processor.py:183} INFO - Processing /home/pkn/e-commerce_data_pipeline/dags/etl_dag.py took 0.033 seconds
[2024-02-16T08:49:52.732+0000] {processor.py:161} INFO - Started process (PID=362973) to work on /home/pkn/e-commerce_data_pipeline/dags/etl_dag.py
[2024-02-16T08:49:52.733+0000] {processor.py:830} INFO - Processing file /home/pkn/e-commerce_data_pipeline/dags/etl_dag.py for tasks to queue
[2024-02-16T08:49:52.734+0000] {logging_mixin.py:188} INFO - [2024-02-16T08:49:52.734+0000] {dagbag.py:538} INFO - Filling up the DagBag from /home/pkn/e-commerce_data_pipeline/dags/etl_dag.py
[2024-02-16T08:49:52.742+0000] {logging_mixin.py:188} INFO - [2024-02-16T08:49:52.741+0000] {dagbag.py:348} ERROR - Failed to import: /home/pkn/e-commerce_data_pipeline/dags/etl_dag.py
Traceback (most recent call last):
  File "/home/pkn/e-commerce_data_pipeline/venv/lib/python3.10/site-packages/airflow/models/dagbag.py", line 344, in parse
    loader.exec_module(new_module)
  File "<frozen importlib._bootstrap_external>", line 883, in exec_module
  File "<frozen importlib._bootstrap>", line 241, in _call_with_frames_removed
  File "/home/pkn/e-commerce_data_pipeline/dags/etl_dag.py", line 29, in <module>
    python_callable = clean_transform_main,
NameError: name 'clean_transform_main' is not defined
[2024-02-16T08:49:52.742+0000] {processor.py:842} WARNING - No viable dags retrieved from /home/pkn/e-commerce_data_pipeline/dags/etl_dag.py
[2024-02-16T08:49:52.774+0000] {processor.py:183} INFO - Processing /home/pkn/e-commerce_data_pipeline/dags/etl_dag.py took 0.048 seconds
[2024-02-16T08:50:23.023+0000] {processor.py:161} INFO - Started process (PID=363166) to work on /home/pkn/e-commerce_data_pipeline/dags/etl_dag.py
[2024-02-16T08:50:23.025+0000] {processor.py:830} INFO - Processing file /home/pkn/e-commerce_data_pipeline/dags/etl_dag.py for tasks to queue
[2024-02-16T08:50:23.026+0000] {logging_mixin.py:188} INFO - [2024-02-16T08:50:23.026+0000] {dagbag.py:538} INFO - Filling up the DagBag from /home/pkn/e-commerce_data_pipeline/dags/etl_dag.py
[2024-02-16T08:50:23.034+0000] {logging_mixin.py:188} INFO - [2024-02-16T08:50:23.033+0000] {dagbag.py:348} ERROR - Failed to import: /home/pkn/e-commerce_data_pipeline/dags/etl_dag.py
Traceback (most recent call last):
  File "/home/pkn/e-commerce_data_pipeline/venv/lib/python3.10/site-packages/airflow/models/dagbag.py", line 344, in parse
    loader.exec_module(new_module)
  File "<frozen importlib._bootstrap_external>", line 883, in exec_module
  File "<frozen importlib._bootstrap>", line 241, in _call_with_frames_removed
  File "/home/pkn/e-commerce_data_pipeline/dags/etl_dag.py", line 29, in <module>
    python_callable = clean_transform_main,
NameError: name 'clean_transform_main' is not defined
[2024-02-16T08:50:23.034+0000] {processor.py:842} WARNING - No viable dags retrieved from /home/pkn/e-commerce_data_pipeline/dags/etl_dag.py
[2024-02-16T08:50:23.060+0000] {processor.py:183} INFO - Processing /home/pkn/e-commerce_data_pipeline/dags/etl_dag.py took 0.041 seconds
[2024-02-16T08:50:54.010+0000] {processor.py:161} INFO - Started process (PID=363389) to work on /home/pkn/e-commerce_data_pipeline/dags/etl_dag.py
[2024-02-16T08:50:54.021+0000] {processor.py:830} INFO - Processing file /home/pkn/e-commerce_data_pipeline/dags/etl_dag.py for tasks to queue
[2024-02-16T08:50:54.022+0000] {logging_mixin.py:188} INFO - [2024-02-16T08:50:54.021+0000] {dagbag.py:538} INFO - Filling up the DagBag from /home/pkn/e-commerce_data_pipeline/dags/etl_dag.py
[2024-02-16T08:50:54.030+0000] {logging_mixin.py:188} INFO - [2024-02-16T08:50:54.029+0000] {dagbag.py:348} ERROR - Failed to import: /home/pkn/e-commerce_data_pipeline/dags/etl_dag.py
Traceback (most recent call last):
  File "/home/pkn/e-commerce_data_pipeline/venv/lib/python3.10/site-packages/airflow/models/dagbag.py", line 344, in parse
    loader.exec_module(new_module)
  File "<frozen importlib._bootstrap_external>", line 883, in exec_module
  File "<frozen importlib._bootstrap>", line 241, in _call_with_frames_removed
  File "/home/pkn/e-commerce_data_pipeline/dags/etl_dag.py", line 29, in <module>
    python_callable = clean_transform_main,
NameError: name 'clean_transform_main' is not defined
[2024-02-16T08:50:54.030+0000] {processor.py:842} WARNING - No viable dags retrieved from /home/pkn/e-commerce_data_pipeline/dags/etl_dag.py
[2024-02-16T08:50:54.061+0000] {processor.py:183} INFO - Processing /home/pkn/e-commerce_data_pipeline/dags/etl_dag.py took 0.056 seconds
[2024-02-16T08:51:24.954+0000] {processor.py:161} INFO - Started process (PID=363609) to work on /home/pkn/e-commerce_data_pipeline/dags/etl_dag.py
[2024-02-16T08:51:24.956+0000] {processor.py:830} INFO - Processing file /home/pkn/e-commerce_data_pipeline/dags/etl_dag.py for tasks to queue
[2024-02-16T08:51:24.957+0000] {logging_mixin.py:188} INFO - [2024-02-16T08:51:24.956+0000] {dagbag.py:538} INFO - Filling up the DagBag from /home/pkn/e-commerce_data_pipeline/dags/etl_dag.py
[2024-02-16T08:51:24.966+0000] {logging_mixin.py:188} INFO - [2024-02-16T08:51:24.966+0000] {dagbag.py:348} ERROR - Failed to import: /home/pkn/e-commerce_data_pipeline/dags/etl_dag.py
Traceback (most recent call last):
  File "/home/pkn/e-commerce_data_pipeline/venv/lib/python3.10/site-packages/airflow/models/dagbag.py", line 344, in parse
    loader.exec_module(new_module)
  File "<frozen importlib._bootstrap_external>", line 883, in exec_module
  File "<frozen importlib._bootstrap>", line 241, in _call_with_frames_removed
  File "/home/pkn/e-commerce_data_pipeline/dags/etl_dag.py", line 29, in <module>
    python_callable = clean_transform_main,
NameError: name 'clean_transform_main' is not defined
[2024-02-16T08:51:24.967+0000] {processor.py:842} WARNING - No viable dags retrieved from /home/pkn/e-commerce_data_pipeline/dags/etl_dag.py
[2024-02-16T08:51:24.999+0000] {processor.py:183} INFO - Processing /home/pkn/e-commerce_data_pipeline/dags/etl_dag.py took 0.048 seconds
[2024-02-16T08:51:55.335+0000] {processor.py:161} INFO - Started process (PID=363899) to work on /home/pkn/e-commerce_data_pipeline/dags/etl_dag.py
[2024-02-16T08:51:55.337+0000] {processor.py:830} INFO - Processing file /home/pkn/e-commerce_data_pipeline/dags/etl_dag.py for tasks to queue
[2024-02-16T08:51:55.338+0000] {logging_mixin.py:188} INFO - [2024-02-16T08:51:55.337+0000] {dagbag.py:538} INFO - Filling up the DagBag from /home/pkn/e-commerce_data_pipeline/dags/etl_dag.py
[2024-02-16T08:51:55.346+0000] {logging_mixin.py:188} INFO - [2024-02-16T08:51:55.345+0000] {dagbag.py:348} ERROR - Failed to import: /home/pkn/e-commerce_data_pipeline/dags/etl_dag.py
Traceback (most recent call last):
  File "/home/pkn/e-commerce_data_pipeline/venv/lib/python3.10/site-packages/airflow/models/dagbag.py", line 344, in parse
    loader.exec_module(new_module)
  File "<frozen importlib._bootstrap_external>", line 883, in exec_module
  File "<frozen importlib._bootstrap>", line 241, in _call_with_frames_removed
  File "/home/pkn/e-commerce_data_pipeline/dags/etl_dag.py", line 29, in <module>
    python_callable = clean_transform_main,
NameError: name 'clean_transform_main' is not defined
[2024-02-16T08:51:55.346+0000] {processor.py:842} WARNING - No viable dags retrieved from /home/pkn/e-commerce_data_pipeline/dags/etl_dag.py
[2024-02-16T08:51:55.371+0000] {processor.py:183} INFO - Processing /home/pkn/e-commerce_data_pipeline/dags/etl_dag.py took 0.041 seconds
[2024-02-16T08:52:25.488+0000] {processor.py:161} INFO - Started process (PID=364147) to work on /home/pkn/e-commerce_data_pipeline/dags/etl_dag.py
[2024-02-16T08:52:25.490+0000] {processor.py:830} INFO - Processing file /home/pkn/e-commerce_data_pipeline/dags/etl_dag.py for tasks to queue
[2024-02-16T08:52:25.492+0000] {logging_mixin.py:188} INFO - [2024-02-16T08:52:25.491+0000] {dagbag.py:538} INFO - Filling up the DagBag from /home/pkn/e-commerce_data_pipeline/dags/etl_dag.py
[2024-02-16T08:52:25.499+0000] {logging_mixin.py:188} INFO - [2024-02-16T08:52:25.499+0000] {dagbag.py:348} ERROR - Failed to import: /home/pkn/e-commerce_data_pipeline/dags/etl_dag.py
Traceback (most recent call last):
  File "/home/pkn/e-commerce_data_pipeline/venv/lib/python3.10/site-packages/airflow/models/dagbag.py", line 344, in parse
    loader.exec_module(new_module)
  File "<frozen importlib._bootstrap_external>", line 883, in exec_module
  File "<frozen importlib._bootstrap>", line 241, in _call_with_frames_removed
  File "/home/pkn/e-commerce_data_pipeline/dags/etl_dag.py", line 29, in <module>
    python_callable = clean_transform_main,
NameError: name 'clean_transform_main' is not defined
[2024-02-16T08:52:25.500+0000] {processor.py:842} WARNING - No viable dags retrieved from /home/pkn/e-commerce_data_pipeline/dags/etl_dag.py
[2024-02-16T08:52:25.527+0000] {processor.py:183} INFO - Processing /home/pkn/e-commerce_data_pipeline/dags/etl_dag.py took 0.048 seconds
[2024-02-16T08:52:56.493+0000] {processor.py:161} INFO - Started process (PID=364502) to work on /home/pkn/e-commerce_data_pipeline/dags/etl_dag.py
[2024-02-16T08:52:56.494+0000] {processor.py:830} INFO - Processing file /home/pkn/e-commerce_data_pipeline/dags/etl_dag.py for tasks to queue
[2024-02-16T08:52:56.495+0000] {logging_mixin.py:188} INFO - [2024-02-16T08:52:56.495+0000] {dagbag.py:538} INFO - Filling up the DagBag from /home/pkn/e-commerce_data_pipeline/dags/etl_dag.py
[2024-02-16T08:52:56.502+0000] {logging_mixin.py:188} INFO - [2024-02-16T08:52:56.502+0000] {dagbag.py:348} ERROR - Failed to import: /home/pkn/e-commerce_data_pipeline/dags/etl_dag.py
Traceback (most recent call last):
  File "/home/pkn/e-commerce_data_pipeline/venv/lib/python3.10/site-packages/airflow/models/dagbag.py", line 344, in parse
    loader.exec_module(new_module)
  File "<frozen importlib._bootstrap_external>", line 883, in exec_module
  File "<frozen importlib._bootstrap>", line 241, in _call_with_frames_removed
  File "/home/pkn/e-commerce_data_pipeline/dags/etl_dag.py", line 29, in <module>
    python_callable = clean_transform_main,
NameError: name 'clean_transform_main' is not defined
[2024-02-16T08:52:56.503+0000] {processor.py:842} WARNING - No viable dags retrieved from /home/pkn/e-commerce_data_pipeline/dags/etl_dag.py
[2024-02-16T08:52:56.534+0000] {processor.py:183} INFO - Processing /home/pkn/e-commerce_data_pipeline/dags/etl_dag.py took 0.046 seconds
[2024-02-16T08:53:27.171+0000] {processor.py:161} INFO - Started process (PID=364811) to work on /home/pkn/e-commerce_data_pipeline/dags/etl_dag.py
[2024-02-16T08:53:27.173+0000] {processor.py:830} INFO - Processing file /home/pkn/e-commerce_data_pipeline/dags/etl_dag.py for tasks to queue
[2024-02-16T08:53:27.175+0000] {logging_mixin.py:188} INFO - [2024-02-16T08:53:27.174+0000] {dagbag.py:538} INFO - Filling up the DagBag from /home/pkn/e-commerce_data_pipeline/dags/etl_dag.py
[2024-02-16T08:53:27.182+0000] {logging_mixin.py:188} INFO - [2024-02-16T08:53:27.181+0000] {dagbag.py:348} ERROR - Failed to import: /home/pkn/e-commerce_data_pipeline/dags/etl_dag.py
Traceback (most recent call last):
  File "/home/pkn/e-commerce_data_pipeline/venv/lib/python3.10/site-packages/airflow/models/dagbag.py", line 344, in parse
    loader.exec_module(new_module)
  File "<frozen importlib._bootstrap_external>", line 883, in exec_module
  File "<frozen importlib._bootstrap>", line 241, in _call_with_frames_removed
  File "/home/pkn/e-commerce_data_pipeline/dags/etl_dag.py", line 29, in <module>
    python_callable = clean_transform_main,
NameError: name 'clean_transform_main' is not defined
[2024-02-16T08:53:27.182+0000] {processor.py:842} WARNING - No viable dags retrieved from /home/pkn/e-commerce_data_pipeline/dags/etl_dag.py
[2024-02-16T08:53:27.214+0000] {processor.py:183} INFO - Processing /home/pkn/e-commerce_data_pipeline/dags/etl_dag.py took 0.049 seconds
[2024-02-16T08:53:57.650+0000] {processor.py:161} INFO - Started process (PID=365122) to work on /home/pkn/e-commerce_data_pipeline/dags/etl_dag.py
[2024-02-16T08:53:57.652+0000] {processor.py:830} INFO - Processing file /home/pkn/e-commerce_data_pipeline/dags/etl_dag.py for tasks to queue
[2024-02-16T08:53:57.653+0000] {logging_mixin.py:188} INFO - [2024-02-16T08:53:57.652+0000] {dagbag.py:538} INFO - Filling up the DagBag from /home/pkn/e-commerce_data_pipeline/dags/etl_dag.py
[2024-02-16T08:53:57.660+0000] {logging_mixin.py:188} INFO - [2024-02-16T08:53:57.659+0000] {dagbag.py:348} ERROR - Failed to import: /home/pkn/e-commerce_data_pipeline/dags/etl_dag.py
Traceback (most recent call last):
  File "/home/pkn/e-commerce_data_pipeline/venv/lib/python3.10/site-packages/airflow/models/dagbag.py", line 344, in parse
    loader.exec_module(new_module)
  File "<frozen importlib._bootstrap_external>", line 883, in exec_module
  File "<frozen importlib._bootstrap>", line 241, in _call_with_frames_removed
  File "/home/pkn/e-commerce_data_pipeline/dags/etl_dag.py", line 29, in <module>
    python_callable = clean_transform_main,
NameError: name 'clean_transform_main' is not defined
[2024-02-16T08:53:57.660+0000] {processor.py:842} WARNING - No viable dags retrieved from /home/pkn/e-commerce_data_pipeline/dags/etl_dag.py
[2024-02-16T08:53:57.699+0000] {processor.py:183} INFO - Processing /home/pkn/e-commerce_data_pipeline/dags/etl_dag.py took 0.054 seconds
[2024-02-16T08:54:28.503+0000] {processor.py:161} INFO - Started process (PID=365468) to work on /home/pkn/e-commerce_data_pipeline/dags/etl_dag.py
[2024-02-16T08:54:28.504+0000] {processor.py:830} INFO - Processing file /home/pkn/e-commerce_data_pipeline/dags/etl_dag.py for tasks to queue
[2024-02-16T08:54:28.505+0000] {logging_mixin.py:188} INFO - [2024-02-16T08:54:28.505+0000] {dagbag.py:538} INFO - Filling up the DagBag from /home/pkn/e-commerce_data_pipeline/dags/etl_dag.py
[2024-02-16T08:54:28.513+0000] {logging_mixin.py:188} INFO - [2024-02-16T08:54:28.512+0000] {dagbag.py:348} ERROR - Failed to import: /home/pkn/e-commerce_data_pipeline/dags/etl_dag.py
Traceback (most recent call last):
  File "/home/pkn/e-commerce_data_pipeline/venv/lib/python3.10/site-packages/airflow/models/dagbag.py", line 344, in parse
    loader.exec_module(new_module)
  File "<frozen importlib._bootstrap_external>", line 883, in exec_module
  File "<frozen importlib._bootstrap>", line 241, in _call_with_frames_removed
  File "/home/pkn/e-commerce_data_pipeline/dags/etl_dag.py", line 29, in <module>
    python_callable = clean_transform_main,
NameError: name 'clean_transform_main' is not defined
[2024-02-16T08:54:28.513+0000] {processor.py:842} WARNING - No viable dags retrieved from /home/pkn/e-commerce_data_pipeline/dags/etl_dag.py
[2024-02-16T08:54:28.538+0000] {processor.py:183} INFO - Processing /home/pkn/e-commerce_data_pipeline/dags/etl_dag.py took 0.040 seconds
[2024-02-16T08:54:58.698+0000] {processor.py:161} INFO - Started process (PID=365905) to work on /home/pkn/e-commerce_data_pipeline/dags/etl_dag.py
[2024-02-16T08:54:58.701+0000] {processor.py:830} INFO - Processing file /home/pkn/e-commerce_data_pipeline/dags/etl_dag.py for tasks to queue
[2024-02-16T08:54:58.702+0000] {logging_mixin.py:188} INFO - [2024-02-16T08:54:58.701+0000] {dagbag.py:538} INFO - Filling up the DagBag from /home/pkn/e-commerce_data_pipeline/dags/etl_dag.py
[2024-02-16T08:54:58.709+0000] {logging_mixin.py:188} INFO - [2024-02-16T08:54:58.709+0000] {dagbag.py:348} ERROR - Failed to import: /home/pkn/e-commerce_data_pipeline/dags/etl_dag.py
Traceback (most recent call last):
  File "/home/pkn/e-commerce_data_pipeline/venv/lib/python3.10/site-packages/airflow/models/dagbag.py", line 344, in parse
    loader.exec_module(new_module)
  File "<frozen importlib._bootstrap_external>", line 883, in exec_module
  File "<frozen importlib._bootstrap>", line 241, in _call_with_frames_removed
  File "/home/pkn/e-commerce_data_pipeline/dags/etl_dag.py", line 29, in <module>
    python_callable = clean_transform_main,
NameError: name 'clean_transform_main' is not defined
[2024-02-16T08:54:58.710+0000] {processor.py:842} WARNING - No viable dags retrieved from /home/pkn/e-commerce_data_pipeline/dags/etl_dag.py
[2024-02-16T08:54:58.737+0000] {processor.py:183} INFO - Processing /home/pkn/e-commerce_data_pipeline/dags/etl_dag.py took 0.043 seconds
[2024-02-16T08:55:29.750+0000] {processor.py:161} INFO - Started process (PID=366308) to work on /home/pkn/e-commerce_data_pipeline/dags/etl_dag.py
[2024-02-16T08:55:29.752+0000] {processor.py:830} INFO - Processing file /home/pkn/e-commerce_data_pipeline/dags/etl_dag.py for tasks to queue
[2024-02-16T08:55:29.753+0000] {logging_mixin.py:188} INFO - [2024-02-16T08:55:29.752+0000] {dagbag.py:538} INFO - Filling up the DagBag from /home/pkn/e-commerce_data_pipeline/dags/etl_dag.py
[2024-02-16T08:55:29.760+0000] {logging_mixin.py:188} INFO - [2024-02-16T08:55:29.760+0000] {dagbag.py:348} ERROR - Failed to import: /home/pkn/e-commerce_data_pipeline/dags/etl_dag.py
Traceback (most recent call last):
  File "/home/pkn/e-commerce_data_pipeline/venv/lib/python3.10/site-packages/airflow/models/dagbag.py", line 344, in parse
    loader.exec_module(new_module)
  File "<frozen importlib._bootstrap_external>", line 883, in exec_module
  File "<frozen importlib._bootstrap>", line 241, in _call_with_frames_removed
  File "/home/pkn/e-commerce_data_pipeline/dags/etl_dag.py", line 29, in <module>
    python_callable = clean_transform_main,
NameError: name 'clean_transform_main' is not defined
[2024-02-16T08:55:29.761+0000] {processor.py:842} WARNING - No viable dags retrieved from /home/pkn/e-commerce_data_pipeline/dags/etl_dag.py
[2024-02-16T08:55:29.787+0000] {processor.py:183} INFO - Processing /home/pkn/e-commerce_data_pipeline/dags/etl_dag.py took 0.043 seconds
[2024-02-16T08:56:00.635+0000] {processor.py:161} INFO - Started process (PID=366643) to work on /home/pkn/e-commerce_data_pipeline/dags/etl_dag.py
[2024-02-16T08:56:00.637+0000] {processor.py:830} INFO - Processing file /home/pkn/e-commerce_data_pipeline/dags/etl_dag.py for tasks to queue
[2024-02-16T08:56:00.638+0000] {logging_mixin.py:188} INFO - [2024-02-16T08:56:00.638+0000] {dagbag.py:538} INFO - Filling up the DagBag from /home/pkn/e-commerce_data_pipeline/dags/etl_dag.py
[2024-02-16T08:56:00.646+0000] {logging_mixin.py:188} INFO - [2024-02-16T08:56:00.645+0000] {dagbag.py:348} ERROR - Failed to import: /home/pkn/e-commerce_data_pipeline/dags/etl_dag.py
Traceback (most recent call last):
  File "/home/pkn/e-commerce_data_pipeline/venv/lib/python3.10/site-packages/airflow/models/dagbag.py", line 344, in parse
    loader.exec_module(new_module)
  File "<frozen importlib._bootstrap_external>", line 883, in exec_module
  File "<frozen importlib._bootstrap>", line 241, in _call_with_frames_removed
  File "/home/pkn/e-commerce_data_pipeline/dags/etl_dag.py", line 29, in <module>
    python_callable = clean_transform_main,
NameError: name 'clean_transform_main' is not defined
[2024-02-16T08:56:00.646+0000] {processor.py:842} WARNING - No viable dags retrieved from /home/pkn/e-commerce_data_pipeline/dags/etl_dag.py
[2024-02-16T08:56:00.688+0000] {processor.py:183} INFO - Processing /home/pkn/e-commerce_data_pipeline/dags/etl_dag.py took 0.060 seconds
[2024-02-16T08:56:31.115+0000] {processor.py:161} INFO - Started process (PID=366953) to work on /home/pkn/e-commerce_data_pipeline/dags/etl_dag.py
[2024-02-16T08:56:31.116+0000] {processor.py:830} INFO - Processing file /home/pkn/e-commerce_data_pipeline/dags/etl_dag.py for tasks to queue
[2024-02-16T08:56:31.117+0000] {logging_mixin.py:188} INFO - [2024-02-16T08:56:31.116+0000] {dagbag.py:538} INFO - Filling up the DagBag from /home/pkn/e-commerce_data_pipeline/dags/etl_dag.py
[2024-02-16T08:56:31.124+0000] {logging_mixin.py:188} INFO - [2024-02-16T08:56:31.123+0000] {dagbag.py:348} ERROR - Failed to import: /home/pkn/e-commerce_data_pipeline/dags/etl_dag.py
Traceback (most recent call last):
  File "/home/pkn/e-commerce_data_pipeline/venv/lib/python3.10/site-packages/airflow/models/dagbag.py", line 344, in parse
    loader.exec_module(new_module)
  File "<frozen importlib._bootstrap_external>", line 883, in exec_module
  File "<frozen importlib._bootstrap>", line 241, in _call_with_frames_removed
  File "/home/pkn/e-commerce_data_pipeline/dags/etl_dag.py", line 29, in <module>
    python_callable = clean_transform_main,
NameError: name 'clean_transform_main' is not defined
[2024-02-16T08:56:31.124+0000] {processor.py:842} WARNING - No viable dags retrieved from /home/pkn/e-commerce_data_pipeline/dags/etl_dag.py
[2024-02-16T08:56:31.149+0000] {processor.py:183} INFO - Processing /home/pkn/e-commerce_data_pipeline/dags/etl_dag.py took 0.040 seconds
[2024-02-16T08:57:02.166+0000] {processor.py:161} INFO - Started process (PID=367285) to work on /home/pkn/e-commerce_data_pipeline/dags/etl_dag.py
[2024-02-16T08:57:02.171+0000] {processor.py:830} INFO - Processing file /home/pkn/e-commerce_data_pipeline/dags/etl_dag.py for tasks to queue
[2024-02-16T08:57:02.175+0000] {logging_mixin.py:188} INFO - [2024-02-16T08:57:02.174+0000] {dagbag.py:538} INFO - Filling up the DagBag from /home/pkn/e-commerce_data_pipeline/dags/etl_dag.py
[2024-02-16T08:57:02.186+0000] {logging_mixin.py:188} INFO - [2024-02-16T08:57:02.185+0000] {dagbag.py:348} ERROR - Failed to import: /home/pkn/e-commerce_data_pipeline/dags/etl_dag.py
Traceback (most recent call last):
  File "/home/pkn/e-commerce_data_pipeline/venv/lib/python3.10/site-packages/airflow/models/dagbag.py", line 344, in parse
    loader.exec_module(new_module)
  File "<frozen importlib._bootstrap_external>", line 883, in exec_module
  File "<frozen importlib._bootstrap>", line 241, in _call_with_frames_removed
  File "/home/pkn/e-commerce_data_pipeline/dags/etl_dag.py", line 29, in <module>
    python_callable = clean_transform_main,
NameError: name 'clean_transform_main' is not defined
[2024-02-16T08:57:02.186+0000] {processor.py:842} WARNING - No viable dags retrieved from /home/pkn/e-commerce_data_pipeline/dags/etl_dag.py
[2024-02-16T08:57:02.216+0000] {processor.py:183} INFO - Processing /home/pkn/e-commerce_data_pipeline/dags/etl_dag.py took 0.056 seconds
[2024-02-16T08:57:33.127+0000] {processor.py:161} INFO - Started process (PID=367599) to work on /home/pkn/e-commerce_data_pipeline/dags/etl_dag.py
[2024-02-16T08:57:33.129+0000] {processor.py:830} INFO - Processing file /home/pkn/e-commerce_data_pipeline/dags/etl_dag.py for tasks to queue
[2024-02-16T08:57:33.130+0000] {logging_mixin.py:188} INFO - [2024-02-16T08:57:33.130+0000] {dagbag.py:538} INFO - Filling up the DagBag from /home/pkn/e-commerce_data_pipeline/dags/etl_dag.py
[2024-02-16T08:57:33.138+0000] {logging_mixin.py:188} INFO - [2024-02-16T08:57:33.137+0000] {dagbag.py:348} ERROR - Failed to import: /home/pkn/e-commerce_data_pipeline/dags/etl_dag.py
Traceback (most recent call last):
  File "/home/pkn/e-commerce_data_pipeline/venv/lib/python3.10/site-packages/airflow/models/dagbag.py", line 344, in parse
    loader.exec_module(new_module)
  File "<frozen importlib._bootstrap_external>", line 883, in exec_module
  File "<frozen importlib._bootstrap>", line 241, in _call_with_frames_removed
  File "/home/pkn/e-commerce_data_pipeline/dags/etl_dag.py", line 29, in <module>
    python_callable = clean_transform_main,
NameError: name 'clean_transform_main' is not defined
[2024-02-16T08:57:33.139+0000] {processor.py:842} WARNING - No viable dags retrieved from /home/pkn/e-commerce_data_pipeline/dags/etl_dag.py
[2024-02-16T08:57:33.168+0000] {processor.py:183} INFO - Processing /home/pkn/e-commerce_data_pipeline/dags/etl_dag.py took 0.046 seconds
[2024-02-16T08:58:03.915+0000] {processor.py:161} INFO - Started process (PID=367910) to work on /home/pkn/e-commerce_data_pipeline/dags/etl_dag.py
[2024-02-16T08:58:03.917+0000] {processor.py:830} INFO - Processing file /home/pkn/e-commerce_data_pipeline/dags/etl_dag.py for tasks to queue
[2024-02-16T08:58:03.918+0000] {logging_mixin.py:188} INFO - [2024-02-16T08:58:03.918+0000] {dagbag.py:538} INFO - Filling up the DagBag from /home/pkn/e-commerce_data_pipeline/dags/etl_dag.py
[2024-02-16T08:58:03.926+0000] {logging_mixin.py:188} INFO - [2024-02-16T08:58:03.925+0000] {dagbag.py:348} ERROR - Failed to import: /home/pkn/e-commerce_data_pipeline/dags/etl_dag.py
Traceback (most recent call last):
  File "/home/pkn/e-commerce_data_pipeline/venv/lib/python3.10/site-packages/airflow/models/dagbag.py", line 344, in parse
    loader.exec_module(new_module)
  File "<frozen importlib._bootstrap_external>", line 883, in exec_module
  File "<frozen importlib._bootstrap>", line 241, in _call_with_frames_removed
  File "/home/pkn/e-commerce_data_pipeline/dags/etl_dag.py", line 29, in <module>
    python_callable = clean_transform_main,
NameError: name 'clean_transform_main' is not defined
[2024-02-16T08:58:03.926+0000] {processor.py:842} WARNING - No viable dags retrieved from /home/pkn/e-commerce_data_pipeline/dags/etl_dag.py
[2024-02-16T08:58:03.964+0000] {processor.py:183} INFO - Processing /home/pkn/e-commerce_data_pipeline/dags/etl_dag.py took 0.054 seconds
[2024-02-16T08:58:34.171+0000] {processor.py:161} INFO - Started process (PID=368220) to work on /home/pkn/e-commerce_data_pipeline/dags/etl_dag.py
[2024-02-16T08:58:34.174+0000] {processor.py:830} INFO - Processing file /home/pkn/e-commerce_data_pipeline/dags/etl_dag.py for tasks to queue
[2024-02-16T08:58:34.176+0000] {logging_mixin.py:188} INFO - [2024-02-16T08:58:34.175+0000] {dagbag.py:538} INFO - Filling up the DagBag from /home/pkn/e-commerce_data_pipeline/dags/etl_dag.py
[2024-02-16T08:58:34.184+0000] {logging_mixin.py:188} INFO - [2024-02-16T08:58:34.183+0000] {dagbag.py:348} ERROR - Failed to import: /home/pkn/e-commerce_data_pipeline/dags/etl_dag.py
Traceback (most recent call last):
  File "/home/pkn/e-commerce_data_pipeline/venv/lib/python3.10/site-packages/airflow/models/dagbag.py", line 344, in parse
    loader.exec_module(new_module)
  File "<frozen importlib._bootstrap_external>", line 883, in exec_module
  File "<frozen importlib._bootstrap>", line 241, in _call_with_frames_removed
  File "/home/pkn/e-commerce_data_pipeline/dags/etl_dag.py", line 29, in <module>
    python_callable = clean_transform_main,
NameError: name 'clean_transform_main' is not defined
[2024-02-16T08:58:34.184+0000] {processor.py:842} WARNING - No viable dags retrieved from /home/pkn/e-commerce_data_pipeline/dags/etl_dag.py
[2024-02-16T08:58:34.213+0000] {processor.py:183} INFO - Processing /home/pkn/e-commerce_data_pipeline/dags/etl_dag.py took 0.053 seconds
[2024-02-16T08:59:04.331+0000] {processor.py:161} INFO - Started process (PID=368506) to work on /home/pkn/e-commerce_data_pipeline/dags/etl_dag.py
[2024-02-16T08:59:04.333+0000] {processor.py:830} INFO - Processing file /home/pkn/e-commerce_data_pipeline/dags/etl_dag.py for tasks to queue
[2024-02-16T08:59:04.335+0000] {logging_mixin.py:188} INFO - [2024-02-16T08:59:04.334+0000] {dagbag.py:538} INFO - Filling up the DagBag from /home/pkn/e-commerce_data_pipeline/dags/etl_dag.py
[2024-02-16T08:59:04.344+0000] {logging_mixin.py:188} INFO - [2024-02-16T08:59:04.343+0000] {dagbag.py:348} ERROR - Failed to import: /home/pkn/e-commerce_data_pipeline/dags/etl_dag.py
Traceback (most recent call last):
  File "/home/pkn/e-commerce_data_pipeline/venv/lib/python3.10/site-packages/airflow/models/dagbag.py", line 344, in parse
    loader.exec_module(new_module)
  File "<frozen importlib._bootstrap_external>", line 883, in exec_module
  File "<frozen importlib._bootstrap>", line 241, in _call_with_frames_removed
  File "/home/pkn/e-commerce_data_pipeline/dags/etl_dag.py", line 29, in <module>
    python_callable = clean_transform_main,
NameError: name 'clean_transform_main' is not defined
[2024-02-16T08:59:04.344+0000] {processor.py:842} WARNING - No viable dags retrieved from /home/pkn/e-commerce_data_pipeline/dags/etl_dag.py
[2024-02-16T08:59:04.372+0000] {processor.py:183} INFO - Processing /home/pkn/e-commerce_data_pipeline/dags/etl_dag.py took 0.046 seconds
[2024-02-16T08:59:34.817+0000] {processor.py:161} INFO - Started process (PID=368819) to work on /home/pkn/e-commerce_data_pipeline/dags/etl_dag.py
[2024-02-16T08:59:34.834+0000] {processor.py:830} INFO - Processing file /home/pkn/e-commerce_data_pipeline/dags/etl_dag.py for tasks to queue
[2024-02-16T08:59:34.836+0000] {logging_mixin.py:188} INFO - [2024-02-16T08:59:34.835+0000] {dagbag.py:538} INFO - Filling up the DagBag from /home/pkn/e-commerce_data_pipeline/dags/etl_dag.py
[2024-02-16T08:59:34.845+0000] {logging_mixin.py:188} INFO - [2024-02-16T08:59:34.844+0000] {dagbag.py:348} ERROR - Failed to import: /home/pkn/e-commerce_data_pipeline/dags/etl_dag.py
Traceback (most recent call last):
  File "/home/pkn/e-commerce_data_pipeline/venv/lib/python3.10/site-packages/airflow/models/dagbag.py", line 344, in parse
    loader.exec_module(new_module)
  File "<frozen importlib._bootstrap_external>", line 883, in exec_module
  File "<frozen importlib._bootstrap>", line 241, in _call_with_frames_removed
  File "/home/pkn/e-commerce_data_pipeline/dags/etl_dag.py", line 29, in <module>
    python_callable = clean_transform_main,
NameError: name 'clean_transform_main' is not defined
[2024-02-16T08:59:34.845+0000] {processor.py:842} WARNING - No viable dags retrieved from /home/pkn/e-commerce_data_pipeline/dags/etl_dag.py
[2024-02-16T08:59:34.873+0000] {processor.py:183} INFO - Processing /home/pkn/e-commerce_data_pipeline/dags/etl_dag.py took 0.061 seconds
[2024-02-16T09:00:05.205+0000] {processor.py:161} INFO - Started process (PID=369138) to work on /home/pkn/e-commerce_data_pipeline/dags/etl_dag.py
[2024-02-16T09:00:05.206+0000] {processor.py:830} INFO - Processing file /home/pkn/e-commerce_data_pipeline/dags/etl_dag.py for tasks to queue
[2024-02-16T09:00:05.207+0000] {logging_mixin.py:188} INFO - [2024-02-16T09:00:05.207+0000] {dagbag.py:538} INFO - Filling up the DagBag from /home/pkn/e-commerce_data_pipeline/dags/etl_dag.py
[2024-02-16T09:00:05.214+0000] {logging_mixin.py:188} INFO - [2024-02-16T09:00:05.214+0000] {dagbag.py:348} ERROR - Failed to import: /home/pkn/e-commerce_data_pipeline/dags/etl_dag.py
Traceback (most recent call last):
  File "/home/pkn/e-commerce_data_pipeline/venv/lib/python3.10/site-packages/airflow/models/dagbag.py", line 344, in parse
    loader.exec_module(new_module)
  File "<frozen importlib._bootstrap_external>", line 883, in exec_module
  File "<frozen importlib._bootstrap>", line 241, in _call_with_frames_removed
  File "/home/pkn/e-commerce_data_pipeline/dags/etl_dag.py", line 29, in <module>
    python_callable = clean_transform_main,
NameError: name 'clean_transform_main' is not defined
[2024-02-16T09:00:05.215+0000] {processor.py:842} WARNING - No viable dags retrieved from /home/pkn/e-commerce_data_pipeline/dags/etl_dag.py
[2024-02-16T09:00:05.248+0000] {processor.py:183} INFO - Processing /home/pkn/e-commerce_data_pipeline/dags/etl_dag.py took 0.048 seconds
[2024-02-16T09:00:35.565+0000] {processor.py:161} INFO - Started process (PID=369336) to work on /home/pkn/e-commerce_data_pipeline/dags/etl_dag.py
[2024-02-16T09:00:35.567+0000] {processor.py:830} INFO - Processing file /home/pkn/e-commerce_data_pipeline/dags/etl_dag.py for tasks to queue
[2024-02-16T09:00:35.568+0000] {logging_mixin.py:188} INFO - [2024-02-16T09:00:35.567+0000] {dagbag.py:538} INFO - Filling up the DagBag from /home/pkn/e-commerce_data_pipeline/dags/etl_dag.py
[2024-02-16T09:00:35.575+0000] {logging_mixin.py:188} INFO - [2024-02-16T09:00:35.575+0000] {dagbag.py:348} ERROR - Failed to import: /home/pkn/e-commerce_data_pipeline/dags/etl_dag.py
Traceback (most recent call last):
  File "/home/pkn/e-commerce_data_pipeline/venv/lib/python3.10/site-packages/airflow/models/dagbag.py", line 344, in parse
    loader.exec_module(new_module)
  File "<frozen importlib._bootstrap_external>", line 883, in exec_module
  File "<frozen importlib._bootstrap>", line 241, in _call_with_frames_removed
  File "/home/pkn/e-commerce_data_pipeline/dags/etl_dag.py", line 29, in <module>
    python_callable = clean_transform_main,
NameError: name 'clean_transform_main' is not defined
[2024-02-16T09:00:35.576+0000] {processor.py:842} WARNING - No viable dags retrieved from /home/pkn/e-commerce_data_pipeline/dags/etl_dag.py
[2024-02-16T09:00:35.608+0000] {processor.py:183} INFO - Processing /home/pkn/e-commerce_data_pipeline/dags/etl_dag.py took 0.048 seconds
[2024-02-16T09:01:05.775+0000] {processor.py:161} INFO - Started process (PID=369580) to work on /home/pkn/e-commerce_data_pipeline/dags/etl_dag.py
[2024-02-16T09:01:05.776+0000] {processor.py:830} INFO - Processing file /home/pkn/e-commerce_data_pipeline/dags/etl_dag.py for tasks to queue
[2024-02-16T09:01:05.777+0000] {logging_mixin.py:188} INFO - [2024-02-16T09:01:05.777+0000] {dagbag.py:538} INFO - Filling up the DagBag from /home/pkn/e-commerce_data_pipeline/dags/etl_dag.py
[2024-02-16T09:01:05.785+0000] {logging_mixin.py:188} INFO - [2024-02-16T09:01:05.784+0000] {dagbag.py:348} ERROR - Failed to import: /home/pkn/e-commerce_data_pipeline/dags/etl_dag.py
Traceback (most recent call last):
  File "/home/pkn/e-commerce_data_pipeline/venv/lib/python3.10/site-packages/airflow/models/dagbag.py", line 344, in parse
    loader.exec_module(new_module)
  File "<frozen importlib._bootstrap_external>", line 883, in exec_module
  File "<frozen importlib._bootstrap>", line 241, in _call_with_frames_removed
  File "/home/pkn/e-commerce_data_pipeline/dags/etl_dag.py", line 29, in <module>
    python_callable = clean_transform_main,
NameError: name 'clean_transform_main' is not defined
[2024-02-16T09:01:05.785+0000] {processor.py:842} WARNING - No viable dags retrieved from /home/pkn/e-commerce_data_pipeline/dags/etl_dag.py
[2024-02-16T09:01:05.818+0000] {processor.py:183} INFO - Processing /home/pkn/e-commerce_data_pipeline/dags/etl_dag.py took 0.048 seconds
[2024-02-16T09:01:35.895+0000] {processor.py:161} INFO - Started process (PID=369776) to work on /home/pkn/e-commerce_data_pipeline/dags/etl_dag.py
[2024-02-16T09:01:35.897+0000] {processor.py:830} INFO - Processing file /home/pkn/e-commerce_data_pipeline/dags/etl_dag.py for tasks to queue
[2024-02-16T09:01:35.898+0000] {logging_mixin.py:188} INFO - [2024-02-16T09:01:35.897+0000] {dagbag.py:538} INFO - Filling up the DagBag from /home/pkn/e-commerce_data_pipeline/dags/etl_dag.py
[2024-02-16T09:01:35.905+0000] {logging_mixin.py:188} INFO - [2024-02-16T09:01:35.905+0000] {dagbag.py:348} ERROR - Failed to import: /home/pkn/e-commerce_data_pipeline/dags/etl_dag.py
Traceback (most recent call last):
  File "/home/pkn/e-commerce_data_pipeline/venv/lib/python3.10/site-packages/airflow/models/dagbag.py", line 344, in parse
    loader.exec_module(new_module)
  File "<frozen importlib._bootstrap_external>", line 883, in exec_module
  File "<frozen importlib._bootstrap>", line 241, in _call_with_frames_removed
  File "/home/pkn/e-commerce_data_pipeline/dags/etl_dag.py", line 29, in <module>
    python_callable = clean_transform_main,
NameError: name 'clean_transform_main' is not defined
[2024-02-16T09:01:35.906+0000] {processor.py:842} WARNING - No viable dags retrieved from /home/pkn/e-commerce_data_pipeline/dags/etl_dag.py
[2024-02-16T09:01:35.939+0000] {processor.py:183} INFO - Processing /home/pkn/e-commerce_data_pipeline/dags/etl_dag.py took 0.050 seconds
[2024-02-16T09:02:06.015+0000] {processor.py:161} INFO - Started process (PID=370013) to work on /home/pkn/e-commerce_data_pipeline/dags/etl_dag.py
[2024-02-16T09:02:06.017+0000] {processor.py:830} INFO - Processing file /home/pkn/e-commerce_data_pipeline/dags/etl_dag.py for tasks to queue
[2024-02-16T09:02:06.018+0000] {logging_mixin.py:188} INFO - [2024-02-16T09:02:06.018+0000] {dagbag.py:538} INFO - Filling up the DagBag from /home/pkn/e-commerce_data_pipeline/dags/etl_dag.py
[2024-02-16T09:02:06.026+0000] {logging_mixin.py:188} INFO - [2024-02-16T09:02:06.025+0000] {dagbag.py:348} ERROR - Failed to import: /home/pkn/e-commerce_data_pipeline/dags/etl_dag.py
Traceback (most recent call last):
  File "/home/pkn/e-commerce_data_pipeline/venv/lib/python3.10/site-packages/airflow/models/dagbag.py", line 344, in parse
    loader.exec_module(new_module)
  File "<frozen importlib._bootstrap_external>", line 883, in exec_module
  File "<frozen importlib._bootstrap>", line 241, in _call_with_frames_removed
  File "/home/pkn/e-commerce_data_pipeline/dags/etl_dag.py", line 29, in <module>
    python_callable = clean_transform_main,
NameError: name 'clean_transform_main' is not defined
[2024-02-16T09:02:06.026+0000] {processor.py:842} WARNING - No viable dags retrieved from /home/pkn/e-commerce_data_pipeline/dags/etl_dag.py
[2024-02-16T09:02:06.052+0000] {processor.py:183} INFO - Processing /home/pkn/e-commerce_data_pipeline/dags/etl_dag.py took 0.043 seconds
[2024-02-16T09:02:36.333+0000] {processor.py:161} INFO - Started process (PID=370284) to work on /home/pkn/e-commerce_data_pipeline/dags/etl_dag.py
[2024-02-16T09:02:36.342+0000] {processor.py:830} INFO - Processing file /home/pkn/e-commerce_data_pipeline/dags/etl_dag.py for tasks to queue
[2024-02-16T09:02:36.343+0000] {logging_mixin.py:188} INFO - [2024-02-16T09:02:36.343+0000] {dagbag.py:538} INFO - Filling up the DagBag from /home/pkn/e-commerce_data_pipeline/dags/etl_dag.py
[2024-02-16T09:02:36.352+0000] {logging_mixin.py:188} INFO - [2024-02-16T09:02:36.351+0000] {dagbag.py:348} ERROR - Failed to import: /home/pkn/e-commerce_data_pipeline/dags/etl_dag.py
Traceback (most recent call last):
  File "/home/pkn/e-commerce_data_pipeline/venv/lib/python3.10/site-packages/airflow/models/dagbag.py", line 344, in parse
    loader.exec_module(new_module)
  File "<frozen importlib._bootstrap_external>", line 883, in exec_module
  File "<frozen importlib._bootstrap>", line 241, in _call_with_frames_removed
  File "/home/pkn/e-commerce_data_pipeline/dags/etl_dag.py", line 29, in <module>
    python_callable = clean_transform_main,
NameError: name 'clean_transform_main' is not defined
[2024-02-16T09:02:36.353+0000] {processor.py:842} WARNING - No viable dags retrieved from /home/pkn/e-commerce_data_pipeline/dags/etl_dag.py
[2024-02-16T09:02:36.378+0000] {processor.py:183} INFO - Processing /home/pkn/e-commerce_data_pipeline/dags/etl_dag.py took 0.051 seconds
[2024-02-16T09:03:06.518+0000] {processor.py:161} INFO - Started process (PID=370593) to work on /home/pkn/e-commerce_data_pipeline/dags/etl_dag.py
[2024-02-16T09:03:06.520+0000] {processor.py:830} INFO - Processing file /home/pkn/e-commerce_data_pipeline/dags/etl_dag.py for tasks to queue
[2024-02-16T09:03:06.521+0000] {logging_mixin.py:188} INFO - [2024-02-16T09:03:06.520+0000] {dagbag.py:538} INFO - Filling up the DagBag from /home/pkn/e-commerce_data_pipeline/dags/etl_dag.py
[2024-02-16T09:03:06.529+0000] {logging_mixin.py:188} INFO - [2024-02-16T09:03:06.528+0000] {dagbag.py:348} ERROR - Failed to import: /home/pkn/e-commerce_data_pipeline/dags/etl_dag.py
Traceback (most recent call last):
  File "/home/pkn/e-commerce_data_pipeline/venv/lib/python3.10/site-packages/airflow/models/dagbag.py", line 344, in parse
    loader.exec_module(new_module)
  File "<frozen importlib._bootstrap_external>", line 883, in exec_module
  File "<frozen importlib._bootstrap>", line 241, in _call_with_frames_removed
  File "/home/pkn/e-commerce_data_pipeline/dags/etl_dag.py", line 29, in <module>
    python_callable = clean_transform_main,
NameError: name 'clean_transform_main' is not defined
[2024-02-16T09:03:06.529+0000] {processor.py:842} WARNING - No viable dags retrieved from /home/pkn/e-commerce_data_pipeline/dags/etl_dag.py
[2024-02-16T09:03:06.574+0000] {processor.py:183} INFO - Processing /home/pkn/e-commerce_data_pipeline/dags/etl_dag.py took 0.062 seconds
[2024-02-16T09:03:36.618+0000] {processor.py:161} INFO - Started process (PID=370813) to work on /home/pkn/e-commerce_data_pipeline/dags/etl_dag.py
[2024-02-16T09:03:36.620+0000] {processor.py:830} INFO - Processing file /home/pkn/e-commerce_data_pipeline/dags/etl_dag.py for tasks to queue
[2024-02-16T09:03:36.621+0000] {logging_mixin.py:188} INFO - [2024-02-16T09:03:36.621+0000] {dagbag.py:538} INFO - Filling up the DagBag from /home/pkn/e-commerce_data_pipeline/dags/etl_dag.py
[2024-02-16T09:03:36.629+0000] {logging_mixin.py:188} INFO - [2024-02-16T09:03:36.628+0000] {dagbag.py:348} ERROR - Failed to import: /home/pkn/e-commerce_data_pipeline/dags/etl_dag.py
Traceback (most recent call last):
  File "/home/pkn/e-commerce_data_pipeline/venv/lib/python3.10/site-packages/airflow/models/dagbag.py", line 344, in parse
    loader.exec_module(new_module)
  File "<frozen importlib._bootstrap_external>", line 883, in exec_module
  File "<frozen importlib._bootstrap>", line 241, in _call_with_frames_removed
  File "/home/pkn/e-commerce_data_pipeline/dags/etl_dag.py", line 29, in <module>
    python_callable = clean_transform_main,
NameError: name 'clean_transform_main' is not defined
[2024-02-16T09:03:36.629+0000] {processor.py:842} WARNING - No viable dags retrieved from /home/pkn/e-commerce_data_pipeline/dags/etl_dag.py
[2024-02-16T09:03:36.670+0000] {processor.py:183} INFO - Processing /home/pkn/e-commerce_data_pipeline/dags/etl_dag.py took 0.056 seconds
[2024-02-16T09:04:06.978+0000] {processor.py:161} INFO - Started process (PID=371107) to work on /home/pkn/e-commerce_data_pipeline/dags/etl_dag.py
[2024-02-16T09:04:06.980+0000] {processor.py:830} INFO - Processing file /home/pkn/e-commerce_data_pipeline/dags/etl_dag.py for tasks to queue
[2024-02-16T09:04:06.981+0000] {logging_mixin.py:188} INFO - [2024-02-16T09:04:06.980+0000] {dagbag.py:538} INFO - Filling up the DagBag from /home/pkn/e-commerce_data_pipeline/dags/etl_dag.py
[2024-02-16T09:04:06.988+0000] {logging_mixin.py:188} INFO - [2024-02-16T09:04:06.988+0000] {dagbag.py:348} ERROR - Failed to import: /home/pkn/e-commerce_data_pipeline/dags/etl_dag.py
Traceback (most recent call last):
  File "/home/pkn/e-commerce_data_pipeline/venv/lib/python3.10/site-packages/airflow/models/dagbag.py", line 344, in parse
    loader.exec_module(new_module)
  File "<frozen importlib._bootstrap_external>", line 883, in exec_module
  File "<frozen importlib._bootstrap>", line 241, in _call_with_frames_removed
  File "/home/pkn/e-commerce_data_pipeline/dags/etl_dag.py", line 29, in <module>
    python_callable = clean_transform_main,
NameError: name 'clean_transform_main' is not defined
[2024-02-16T09:04:06.989+0000] {processor.py:842} WARNING - No viable dags retrieved from /home/pkn/e-commerce_data_pipeline/dags/etl_dag.py
[2024-02-16T09:04:07.013+0000] {processor.py:183} INFO - Processing /home/pkn/e-commerce_data_pipeline/dags/etl_dag.py took 0.039 seconds
[2024-02-16T09:04:37.055+0000] {processor.py:161} INFO - Started process (PID=371295) to work on /home/pkn/e-commerce_data_pipeline/dags/etl_dag.py
[2024-02-16T09:04:37.057+0000] {processor.py:830} INFO - Processing file /home/pkn/e-commerce_data_pipeline/dags/etl_dag.py for tasks to queue
[2024-02-16T09:04:37.059+0000] {logging_mixin.py:188} INFO - [2024-02-16T09:04:37.059+0000] {dagbag.py:538} INFO - Filling up the DagBag from /home/pkn/e-commerce_data_pipeline/dags/etl_dag.py
[2024-02-16T09:04:37.067+0000] {logging_mixin.py:188} INFO - [2024-02-16T09:04:37.066+0000] {dagbag.py:348} ERROR - Failed to import: /home/pkn/e-commerce_data_pipeline/dags/etl_dag.py
Traceback (most recent call last):
  File "/home/pkn/e-commerce_data_pipeline/venv/lib/python3.10/site-packages/airflow/models/dagbag.py", line 344, in parse
    loader.exec_module(new_module)
  File "<frozen importlib._bootstrap_external>", line 883, in exec_module
  File "<frozen importlib._bootstrap>", line 241, in _call_with_frames_removed
  File "/home/pkn/e-commerce_data_pipeline/dags/etl_dag.py", line 29, in <module>
    python_callable = clean_transform_main,
NameError: name 'clean_transform_main' is not defined
[2024-02-16T09:04:37.067+0000] {processor.py:842} WARNING - No viable dags retrieved from /home/pkn/e-commerce_data_pipeline/dags/etl_dag.py
[2024-02-16T09:04:37.095+0000] {processor.py:183} INFO - Processing /home/pkn/e-commerce_data_pipeline/dags/etl_dag.py took 0.045 seconds
[2024-02-16T09:05:07.189+0000] {processor.py:161} INFO - Started process (PID=371479) to work on /home/pkn/e-commerce_data_pipeline/dags/etl_dag.py
[2024-02-16T09:05:07.191+0000] {processor.py:830} INFO - Processing file /home/pkn/e-commerce_data_pipeline/dags/etl_dag.py for tasks to queue
[2024-02-16T09:05:07.192+0000] {logging_mixin.py:188} INFO - [2024-02-16T09:05:07.192+0000] {dagbag.py:538} INFO - Filling up the DagBag from /home/pkn/e-commerce_data_pipeline/dags/etl_dag.py
[2024-02-16T09:05:07.198+0000] {logging_mixin.py:188} INFO - [2024-02-16T09:05:07.197+0000] {dagbag.py:348} ERROR - Failed to import: /home/pkn/e-commerce_data_pipeline/dags/etl_dag.py
Traceback (most recent call last):
  File "/home/pkn/e-commerce_data_pipeline/venv/lib/python3.10/site-packages/airflow/models/dagbag.py", line 344, in parse
    loader.exec_module(new_module)
  File "<frozen importlib._bootstrap_external>", line 883, in exec_module
  File "<frozen importlib._bootstrap>", line 241, in _call_with_frames_removed
  File "/home/pkn/e-commerce_data_pipeline/dags/etl_dag.py", line 29, in <module>
    python_callable = clean_transform_main,
NameError: name 'clean_transform_main' is not defined
[2024-02-16T09:05:07.198+0000] {processor.py:842} WARNING - No viable dags retrieved from /home/pkn/e-commerce_data_pipeline/dags/etl_dag.py
[2024-02-16T09:05:07.220+0000] {processor.py:183} INFO - Processing /home/pkn/e-commerce_data_pipeline/dags/etl_dag.py took 0.036 seconds
[2024-02-16T09:05:37.650+0000] {processor.py:161} INFO - Started process (PID=371675) to work on /home/pkn/e-commerce_data_pipeline/dags/etl_dag.py
[2024-02-16T09:05:37.651+0000] {processor.py:830} INFO - Processing file /home/pkn/e-commerce_data_pipeline/dags/etl_dag.py for tasks to queue
[2024-02-16T09:05:37.652+0000] {logging_mixin.py:188} INFO - [2024-02-16T09:05:37.652+0000] {dagbag.py:538} INFO - Filling up the DagBag from /home/pkn/e-commerce_data_pipeline/dags/etl_dag.py
[2024-02-16T09:05:37.658+0000] {logging_mixin.py:188} INFO - [2024-02-16T09:05:37.657+0000] {dagbag.py:348} ERROR - Failed to import: /home/pkn/e-commerce_data_pipeline/dags/etl_dag.py
Traceback (most recent call last):
  File "/home/pkn/e-commerce_data_pipeline/venv/lib/python3.10/site-packages/airflow/models/dagbag.py", line 344, in parse
    loader.exec_module(new_module)
  File "<frozen importlib._bootstrap_external>", line 883, in exec_module
  File "<frozen importlib._bootstrap>", line 241, in _call_with_frames_removed
  File "/home/pkn/e-commerce_data_pipeline/dags/etl_dag.py", line 29, in <module>
    python_callable = clean_transform_main,
NameError: name 'clean_transform_main' is not defined
[2024-02-16T09:05:37.658+0000] {processor.py:842} WARNING - No viable dags retrieved from /home/pkn/e-commerce_data_pipeline/dags/etl_dag.py
[2024-02-16T09:05:37.688+0000] {processor.py:183} INFO - Processing /home/pkn/e-commerce_data_pipeline/dags/etl_dag.py took 0.042 seconds
[2024-02-16T09:06:08.142+0000] {processor.py:161} INFO - Started process (PID=371962) to work on /home/pkn/e-commerce_data_pipeline/dags/etl_dag.py
[2024-02-16T09:06:08.144+0000] {processor.py:830} INFO - Processing file /home/pkn/e-commerce_data_pipeline/dags/etl_dag.py for tasks to queue
[2024-02-16T09:06:08.145+0000] {logging_mixin.py:188} INFO - [2024-02-16T09:06:08.145+0000] {dagbag.py:538} INFO - Filling up the DagBag from /home/pkn/e-commerce_data_pipeline/dags/etl_dag.py
[2024-02-16T09:06:08.152+0000] {logging_mixin.py:188} INFO - [2024-02-16T09:06:08.152+0000] {dagbag.py:348} ERROR - Failed to import: /home/pkn/e-commerce_data_pipeline/dags/etl_dag.py
Traceback (most recent call last):
  File "/home/pkn/e-commerce_data_pipeline/venv/lib/python3.10/site-packages/airflow/models/dagbag.py", line 344, in parse
    loader.exec_module(new_module)
  File "<frozen importlib._bootstrap_external>", line 883, in exec_module
  File "<frozen importlib._bootstrap>", line 241, in _call_with_frames_removed
  File "/home/pkn/e-commerce_data_pipeline/dags/etl_dag.py", line 29, in <module>
    python_callable = clean_transform_main,
NameError: name 'clean_transform_main' is not defined
[2024-02-16T09:06:08.153+0000] {processor.py:842} WARNING - No viable dags retrieved from /home/pkn/e-commerce_data_pipeline/dags/etl_dag.py
[2024-02-16T09:06:08.188+0000] {processor.py:183} INFO - Processing /home/pkn/e-commerce_data_pipeline/dags/etl_dag.py took 0.052 seconds
[2024-02-16T09:06:38.907+0000] {processor.py:161} INFO - Started process (PID=372296) to work on /home/pkn/e-commerce_data_pipeline/dags/etl_dag.py
[2024-02-16T09:06:38.908+0000] {processor.py:830} INFO - Processing file /home/pkn/e-commerce_data_pipeline/dags/etl_dag.py for tasks to queue
[2024-02-16T09:06:38.910+0000] {logging_mixin.py:188} INFO - [2024-02-16T09:06:38.909+0000] {dagbag.py:538} INFO - Filling up the DagBag from /home/pkn/e-commerce_data_pipeline/dags/etl_dag.py
[2024-02-16T09:06:38.917+0000] {logging_mixin.py:188} INFO - [2024-02-16T09:06:38.916+0000] {dagbag.py:348} ERROR - Failed to import: /home/pkn/e-commerce_data_pipeline/dags/etl_dag.py
Traceback (most recent call last):
  File "/home/pkn/e-commerce_data_pipeline/venv/lib/python3.10/site-packages/airflow/models/dagbag.py", line 344, in parse
    loader.exec_module(new_module)
  File "<frozen importlib._bootstrap_external>", line 883, in exec_module
  File "<frozen importlib._bootstrap>", line 241, in _call_with_frames_removed
  File "/home/pkn/e-commerce_data_pipeline/dags/etl_dag.py", line 29, in <module>
    python_callable = clean_transform_main,
NameError: name 'clean_transform_main' is not defined
[2024-02-16T09:06:38.917+0000] {processor.py:842} WARNING - No viable dags retrieved from /home/pkn/e-commerce_data_pipeline/dags/etl_dag.py
[2024-02-16T09:06:38.947+0000] {processor.py:183} INFO - Processing /home/pkn/e-commerce_data_pipeline/dags/etl_dag.py took 0.045 seconds
[2024-02-16T09:07:09.944+0000] {processor.py:161} INFO - Started process (PID=372663) to work on /home/pkn/e-commerce_data_pipeline/dags/etl_dag.py
[2024-02-16T09:07:09.946+0000] {processor.py:830} INFO - Processing file /home/pkn/e-commerce_data_pipeline/dags/etl_dag.py for tasks to queue
[2024-02-16T09:07:09.947+0000] {logging_mixin.py:188} INFO - [2024-02-16T09:07:09.947+0000] {dagbag.py:538} INFO - Filling up the DagBag from /home/pkn/e-commerce_data_pipeline/dags/etl_dag.py
[2024-02-16T09:07:09.954+0000] {logging_mixin.py:188} INFO - [2024-02-16T09:07:09.953+0000] {dagbag.py:348} ERROR - Failed to import: /home/pkn/e-commerce_data_pipeline/dags/etl_dag.py
Traceback (most recent call last):
  File "/home/pkn/e-commerce_data_pipeline/venv/lib/python3.10/site-packages/airflow/models/dagbag.py", line 344, in parse
    loader.exec_module(new_module)
  File "<frozen importlib._bootstrap_external>", line 883, in exec_module
  File "<frozen importlib._bootstrap>", line 241, in _call_with_frames_removed
  File "/home/pkn/e-commerce_data_pipeline/dags/etl_dag.py", line 29, in <module>
    python_callable = clean_transform_main,
NameError: name 'clean_transform_main' is not defined
[2024-02-16T09:07:09.954+0000] {processor.py:842} WARNING - No viable dags retrieved from /home/pkn/e-commerce_data_pipeline/dags/etl_dag.py
[2024-02-16T09:07:09.978+0000] {processor.py:183} INFO - Processing /home/pkn/e-commerce_data_pipeline/dags/etl_dag.py took 0.040 seconds
[2024-02-16T09:07:40.889+0000] {processor.py:161} INFO - Started process (PID=373001) to work on /home/pkn/e-commerce_data_pipeline/dags/etl_dag.py
[2024-02-16T09:07:40.890+0000] {processor.py:830} INFO - Processing file /home/pkn/e-commerce_data_pipeline/dags/etl_dag.py for tasks to queue
[2024-02-16T09:07:40.891+0000] {logging_mixin.py:188} INFO - [2024-02-16T09:07:40.890+0000] {dagbag.py:538} INFO - Filling up the DagBag from /home/pkn/e-commerce_data_pipeline/dags/etl_dag.py
[2024-02-16T09:07:40.901+0000] {logging_mixin.py:188} INFO - [2024-02-16T09:07:40.901+0000] {dagbag.py:348} ERROR - Failed to import: /home/pkn/e-commerce_data_pipeline/dags/etl_dag.py
Traceback (most recent call last):
  File "/home/pkn/e-commerce_data_pipeline/venv/lib/python3.10/site-packages/airflow/models/dagbag.py", line 344, in parse
    loader.exec_module(new_module)
  File "<frozen importlib._bootstrap_external>", line 883, in exec_module
  File "<frozen importlib._bootstrap>", line 241, in _call_with_frames_removed
  File "/home/pkn/e-commerce_data_pipeline/dags/etl_dag.py", line 29, in <module>
    python_callable = clean_transform_main,
NameError: name 'clean_transform_main' is not defined
[2024-02-16T09:07:40.902+0000] {processor.py:842} WARNING - No viable dags retrieved from /home/pkn/e-commerce_data_pipeline/dags/etl_dag.py
[2024-02-16T09:07:40.928+0000] {processor.py:183} INFO - Processing /home/pkn/e-commerce_data_pipeline/dags/etl_dag.py took 0.044 seconds
[2024-02-16T09:08:11.906+0000] {processor.py:161} INFO - Started process (PID=373355) to work on /home/pkn/e-commerce_data_pipeline/dags/etl_dag.py
[2024-02-16T09:08:11.907+0000] {processor.py:830} INFO - Processing file /home/pkn/e-commerce_data_pipeline/dags/etl_dag.py for tasks to queue
[2024-02-16T09:08:11.908+0000] {logging_mixin.py:188} INFO - [2024-02-16T09:08:11.908+0000] {dagbag.py:538} INFO - Filling up the DagBag from /home/pkn/e-commerce_data_pipeline/dags/etl_dag.py
[2024-02-16T09:08:11.915+0000] {logging_mixin.py:188} INFO - [2024-02-16T09:08:11.915+0000] {dagbag.py:348} ERROR - Failed to import: /home/pkn/e-commerce_data_pipeline/dags/etl_dag.py
Traceback (most recent call last):
  File "/home/pkn/e-commerce_data_pipeline/venv/lib/python3.10/site-packages/airflow/models/dagbag.py", line 344, in parse
    loader.exec_module(new_module)
  File "<frozen importlib._bootstrap_external>", line 883, in exec_module
  File "<frozen importlib._bootstrap>", line 241, in _call_with_frames_removed
  File "/home/pkn/e-commerce_data_pipeline/dags/etl_dag.py", line 29, in <module>
    python_callable = clean_transform_main,
NameError: name 'clean_transform_main' is not defined
[2024-02-16T09:08:11.916+0000] {processor.py:842} WARNING - No viable dags retrieved from /home/pkn/e-commerce_data_pipeline/dags/etl_dag.py
[2024-02-16T09:08:11.948+0000] {processor.py:183} INFO - Processing /home/pkn/e-commerce_data_pipeline/dags/etl_dag.py took 0.048 seconds
[2024-02-16T09:08:42.050+0000] {processor.py:161} INFO - Started process (PID=373666) to work on /home/pkn/e-commerce_data_pipeline/dags/etl_dag.py
[2024-02-16T09:08:42.051+0000] {processor.py:830} INFO - Processing file /home/pkn/e-commerce_data_pipeline/dags/etl_dag.py for tasks to queue
[2024-02-16T09:08:42.052+0000] {logging_mixin.py:188} INFO - [2024-02-16T09:08:42.051+0000] {dagbag.py:538} INFO - Filling up the DagBag from /home/pkn/e-commerce_data_pipeline/dags/etl_dag.py
[2024-02-16T09:08:42.059+0000] {logging_mixin.py:188} INFO - [2024-02-16T09:08:42.058+0000] {dagbag.py:348} ERROR - Failed to import: /home/pkn/e-commerce_data_pipeline/dags/etl_dag.py
Traceback (most recent call last):
  File "/home/pkn/e-commerce_data_pipeline/venv/lib/python3.10/site-packages/airflow/models/dagbag.py", line 344, in parse
    loader.exec_module(new_module)
  File "<frozen importlib._bootstrap_external>", line 883, in exec_module
  File "<frozen importlib._bootstrap>", line 241, in _call_with_frames_removed
  File "/home/pkn/e-commerce_data_pipeline/dags/etl_dag.py", line 29, in <module>
    python_callable = clean_transform_main,
NameError: name 'clean_transform_main' is not defined
[2024-02-16T09:08:42.059+0000] {processor.py:842} WARNING - No viable dags retrieved from /home/pkn/e-commerce_data_pipeline/dags/etl_dag.py
[2024-02-16T09:08:42.099+0000] {processor.py:183} INFO - Processing /home/pkn/e-commerce_data_pipeline/dags/etl_dag.py took 0.054 seconds
[2024-02-16T09:09:12.454+0000] {processor.py:161} INFO - Started process (PID=373936) to work on /home/pkn/e-commerce_data_pipeline/dags/etl_dag.py
[2024-02-16T09:09:12.456+0000] {processor.py:830} INFO - Processing file /home/pkn/e-commerce_data_pipeline/dags/etl_dag.py for tasks to queue
[2024-02-16T09:09:12.457+0000] {logging_mixin.py:188} INFO - [2024-02-16T09:09:12.456+0000] {dagbag.py:538} INFO - Filling up the DagBag from /home/pkn/e-commerce_data_pipeline/dags/etl_dag.py
[2024-02-16T09:09:12.465+0000] {logging_mixin.py:188} INFO - [2024-02-16T09:09:12.464+0000] {dagbag.py:348} ERROR - Failed to import: /home/pkn/e-commerce_data_pipeline/dags/etl_dag.py
Traceback (most recent call last):
  File "/home/pkn/e-commerce_data_pipeline/venv/lib/python3.10/site-packages/airflow/models/dagbag.py", line 344, in parse
    loader.exec_module(new_module)
  File "<frozen importlib._bootstrap_external>", line 883, in exec_module
  File "<frozen importlib._bootstrap>", line 241, in _call_with_frames_removed
  File "/home/pkn/e-commerce_data_pipeline/dags/etl_dag.py", line 29, in <module>
    python_callable = clean_transform_main,
NameError: name 'clean_transform_main' is not defined
[2024-02-16T09:09:12.465+0000] {processor.py:842} WARNING - No viable dags retrieved from /home/pkn/e-commerce_data_pipeline/dags/etl_dag.py
[2024-02-16T09:09:12.495+0000] {processor.py:183} INFO - Processing /home/pkn/e-commerce_data_pipeline/dags/etl_dag.py took 0.045 seconds
[2024-02-16T09:09:42.671+0000] {processor.py:161} INFO - Started process (PID=374128) to work on /home/pkn/e-commerce_data_pipeline/dags/etl_dag.py
[2024-02-16T09:09:42.672+0000] {processor.py:830} INFO - Processing file /home/pkn/e-commerce_data_pipeline/dags/etl_dag.py for tasks to queue
[2024-02-16T09:09:42.673+0000] {logging_mixin.py:188} INFO - [2024-02-16T09:09:42.673+0000] {dagbag.py:538} INFO - Filling up the DagBag from /home/pkn/e-commerce_data_pipeline/dags/etl_dag.py
[2024-02-16T09:09:42.680+0000] {logging_mixin.py:188} INFO - [2024-02-16T09:09:42.680+0000] {dagbag.py:348} ERROR - Failed to import: /home/pkn/e-commerce_data_pipeline/dags/etl_dag.py
Traceback (most recent call last):
  File "/home/pkn/e-commerce_data_pipeline/venv/lib/python3.10/site-packages/airflow/models/dagbag.py", line 344, in parse
    loader.exec_module(new_module)
  File "<frozen importlib._bootstrap_external>", line 883, in exec_module
  File "<frozen importlib._bootstrap>", line 241, in _call_with_frames_removed
  File "/home/pkn/e-commerce_data_pipeline/dags/etl_dag.py", line 29, in <module>
    python_callable = clean_transform_main,
NameError: name 'clean_transform_main' is not defined
[2024-02-16T09:09:42.681+0000] {processor.py:842} WARNING - No viable dags retrieved from /home/pkn/e-commerce_data_pipeline/dags/etl_dag.py
[2024-02-16T09:09:42.718+0000] {processor.py:183} INFO - Processing /home/pkn/e-commerce_data_pipeline/dags/etl_dag.py took 0.053 seconds
[2024-02-16T09:10:13.611+0000] {processor.py:161} INFO - Started process (PID=374476) to work on /home/pkn/e-commerce_data_pipeline/dags/etl_dag.py
[2024-02-16T09:10:13.612+0000] {processor.py:830} INFO - Processing file /home/pkn/e-commerce_data_pipeline/dags/etl_dag.py for tasks to queue
[2024-02-16T09:10:13.613+0000] {logging_mixin.py:188} INFO - [2024-02-16T09:10:13.612+0000] {dagbag.py:538} INFO - Filling up the DagBag from /home/pkn/e-commerce_data_pipeline/dags/etl_dag.py
[2024-02-16T09:10:13.619+0000] {logging_mixin.py:188} INFO - [2024-02-16T09:10:13.619+0000] {dagbag.py:348} ERROR - Failed to import: /home/pkn/e-commerce_data_pipeline/dags/etl_dag.py
Traceback (most recent call last):
  File "/home/pkn/e-commerce_data_pipeline/venv/lib/python3.10/site-packages/airflow/models/dagbag.py", line 344, in parse
    loader.exec_module(new_module)
  File "<frozen importlib._bootstrap_external>", line 883, in exec_module
  File "<frozen importlib._bootstrap>", line 241, in _call_with_frames_removed
  File "/home/pkn/e-commerce_data_pipeline/dags/etl_dag.py", line 29, in <module>
    python_callable = clean_transform_main,
NameError: name 'clean_transform_main' is not defined
[2024-02-16T09:10:13.620+0000] {processor.py:842} WARNING - No viable dags retrieved from /home/pkn/e-commerce_data_pipeline/dags/etl_dag.py
[2024-02-16T09:10:13.645+0000] {processor.py:183} INFO - Processing /home/pkn/e-commerce_data_pipeline/dags/etl_dag.py took 0.038 seconds
[2024-02-16T09:10:43.735+0000] {processor.py:161} INFO - Started process (PID=374785) to work on /home/pkn/e-commerce_data_pipeline/dags/etl_dag.py
[2024-02-16T09:10:43.737+0000] {processor.py:830} INFO - Processing file /home/pkn/e-commerce_data_pipeline/dags/etl_dag.py for tasks to queue
[2024-02-16T09:10:43.738+0000] {logging_mixin.py:188} INFO - [2024-02-16T09:10:43.737+0000] {dagbag.py:538} INFO - Filling up the DagBag from /home/pkn/e-commerce_data_pipeline/dags/etl_dag.py
[2024-02-16T09:10:43.745+0000] {logging_mixin.py:188} INFO - [2024-02-16T09:10:43.744+0000] {dagbag.py:348} ERROR - Failed to import: /home/pkn/e-commerce_data_pipeline/dags/etl_dag.py
Traceback (most recent call last):
  File "/home/pkn/e-commerce_data_pipeline/venv/lib/python3.10/site-packages/airflow/models/dagbag.py", line 344, in parse
    loader.exec_module(new_module)
  File "<frozen importlib._bootstrap_external>", line 883, in exec_module
  File "<frozen importlib._bootstrap>", line 241, in _call_with_frames_removed
  File "/home/pkn/e-commerce_data_pipeline/dags/etl_dag.py", line 29, in <module>
    python_callable = clean_transform_main,
NameError: name 'clean_transform_main' is not defined
[2024-02-16T09:10:43.745+0000] {processor.py:842} WARNING - No viable dags retrieved from /home/pkn/e-commerce_data_pipeline/dags/etl_dag.py
[2024-02-16T09:10:43.776+0000] {processor.py:183} INFO - Processing /home/pkn/e-commerce_data_pipeline/dags/etl_dag.py took 0.047 seconds
[2024-02-16T09:11:14.484+0000] {processor.py:161} INFO - Started process (PID=375013) to work on /home/pkn/e-commerce_data_pipeline/dags/etl_dag.py
[2024-02-16T09:11:14.485+0000] {processor.py:830} INFO - Processing file /home/pkn/e-commerce_data_pipeline/dags/etl_dag.py for tasks to queue
[2024-02-16T09:11:14.486+0000] {logging_mixin.py:188} INFO - [2024-02-16T09:11:14.485+0000] {dagbag.py:538} INFO - Filling up the DagBag from /home/pkn/e-commerce_data_pipeline/dags/etl_dag.py
[2024-02-16T09:11:14.493+0000] {logging_mixin.py:188} INFO - [2024-02-16T09:11:14.492+0000] {dagbag.py:348} ERROR - Failed to import: /home/pkn/e-commerce_data_pipeline/dags/etl_dag.py
Traceback (most recent call last):
  File "/home/pkn/e-commerce_data_pipeline/venv/lib/python3.10/site-packages/airflow/models/dagbag.py", line 344, in parse
    loader.exec_module(new_module)
  File "<frozen importlib._bootstrap_external>", line 883, in exec_module
  File "<frozen importlib._bootstrap>", line 241, in _call_with_frames_removed
  File "/home/pkn/e-commerce_data_pipeline/dags/etl_dag.py", line 29, in <module>
    python_callable = clean_transform_main,
NameError: name 'clean_transform_main' is not defined
[2024-02-16T09:11:14.493+0000] {processor.py:842} WARNING - No viable dags retrieved from /home/pkn/e-commerce_data_pipeline/dags/etl_dag.py
[2024-02-16T09:11:14.521+0000] {processor.py:183} INFO - Processing /home/pkn/e-commerce_data_pipeline/dags/etl_dag.py took 0.042 seconds
[2024-02-16T09:11:44.619+0000] {processor.py:161} INFO - Started process (PID=375206) to work on /home/pkn/e-commerce_data_pipeline/dags/etl_dag.py
[2024-02-16T09:11:44.620+0000] {processor.py:830} INFO - Processing file /home/pkn/e-commerce_data_pipeline/dags/etl_dag.py for tasks to queue
[2024-02-16T09:11:44.621+0000] {logging_mixin.py:188} INFO - [2024-02-16T09:11:44.621+0000] {dagbag.py:538} INFO - Filling up the DagBag from /home/pkn/e-commerce_data_pipeline/dags/etl_dag.py
[2024-02-16T09:11:44.628+0000] {logging_mixin.py:188} INFO - [2024-02-16T09:11:44.627+0000] {dagbag.py:348} ERROR - Failed to import: /home/pkn/e-commerce_data_pipeline/dags/etl_dag.py
Traceback (most recent call last):
  File "/home/pkn/e-commerce_data_pipeline/venv/lib/python3.10/site-packages/airflow/models/dagbag.py", line 344, in parse
    loader.exec_module(new_module)
  File "<frozen importlib._bootstrap_external>", line 883, in exec_module
  File "<frozen importlib._bootstrap>", line 241, in _call_with_frames_removed
  File "/home/pkn/e-commerce_data_pipeline/dags/etl_dag.py", line 29, in <module>
    python_callable = clean_transform_main,
NameError: name 'clean_transform_main' is not defined
[2024-02-16T09:11:44.628+0000] {processor.py:842} WARNING - No viable dags retrieved from /home/pkn/e-commerce_data_pipeline/dags/etl_dag.py
[2024-02-16T09:11:44.655+0000] {processor.py:183} INFO - Processing /home/pkn/e-commerce_data_pipeline/dags/etl_dag.py took 0.042 seconds
[2024-02-16T09:12:14.819+0000] {processor.py:161} INFO - Started process (PID=375422) to work on /home/pkn/e-commerce_data_pipeline/dags/etl_dag.py
[2024-02-16T09:12:14.821+0000] {processor.py:830} INFO - Processing file /home/pkn/e-commerce_data_pipeline/dags/etl_dag.py for tasks to queue
[2024-02-16T09:12:14.822+0000] {logging_mixin.py:188} INFO - [2024-02-16T09:12:14.822+0000] {dagbag.py:538} INFO - Filling up the DagBag from /home/pkn/e-commerce_data_pipeline/dags/etl_dag.py
[2024-02-16T09:12:14.829+0000] {logging_mixin.py:188} INFO - [2024-02-16T09:12:14.828+0000] {dagbag.py:348} ERROR - Failed to import: /home/pkn/e-commerce_data_pipeline/dags/etl_dag.py
Traceback (most recent call last):
  File "/home/pkn/e-commerce_data_pipeline/venv/lib/python3.10/site-packages/airflow/models/dagbag.py", line 344, in parse
    loader.exec_module(new_module)
  File "<frozen importlib._bootstrap_external>", line 883, in exec_module
  File "<frozen importlib._bootstrap>", line 241, in _call_with_frames_removed
  File "/home/pkn/e-commerce_data_pipeline/dags/etl_dag.py", line 29, in <module>
    python_callable = clean_transform_main,
NameError: name 'clean_transform_main' is not defined
[2024-02-16T09:12:14.829+0000] {processor.py:842} WARNING - No viable dags retrieved from /home/pkn/e-commerce_data_pipeline/dags/etl_dag.py
[2024-02-16T09:12:14.862+0000] {processor.py:183} INFO - Processing /home/pkn/e-commerce_data_pipeline/dags/etl_dag.py took 0.049 seconds
[2024-02-16T09:12:45.022+0000] {processor.py:161} INFO - Started process (PID=375690) to work on /home/pkn/e-commerce_data_pipeline/dags/etl_dag.py
[2024-02-16T09:12:45.023+0000] {processor.py:830} INFO - Processing file /home/pkn/e-commerce_data_pipeline/dags/etl_dag.py for tasks to queue
[2024-02-16T09:12:45.024+0000] {logging_mixin.py:188} INFO - [2024-02-16T09:12:45.024+0000] {dagbag.py:538} INFO - Filling up the DagBag from /home/pkn/e-commerce_data_pipeline/dags/etl_dag.py
[2024-02-16T09:12:45.031+0000] {logging_mixin.py:188} INFO - [2024-02-16T09:12:45.031+0000] {dagbag.py:348} ERROR - Failed to import: /home/pkn/e-commerce_data_pipeline/dags/etl_dag.py
Traceback (most recent call last):
  File "/home/pkn/e-commerce_data_pipeline/venv/lib/python3.10/site-packages/airflow/models/dagbag.py", line 344, in parse
    loader.exec_module(new_module)
  File "<frozen importlib._bootstrap_external>", line 883, in exec_module
  File "<frozen importlib._bootstrap>", line 241, in _call_with_frames_removed
  File "/home/pkn/e-commerce_data_pipeline/dags/etl_dag.py", line 29, in <module>
    python_callable = clean_transform_main,
NameError: name 'clean_transform_main' is not defined
[2024-02-16T09:12:45.032+0000] {processor.py:842} WARNING - No viable dags retrieved from /home/pkn/e-commerce_data_pipeline/dags/etl_dag.py
[2024-02-16T09:12:45.057+0000] {processor.py:183} INFO - Processing /home/pkn/e-commerce_data_pipeline/dags/etl_dag.py took 0.041 seconds
[2024-02-16T09:12:59.805+0000] {processor.py:161} INFO - Started process (PID=375890) to work on /home/pkn/e-commerce_data_pipeline/dags/etl_dag.py
[2024-02-16T09:12:59.808+0000] {processor.py:830} INFO - Processing file /home/pkn/e-commerce_data_pipeline/dags/etl_dag.py for tasks to queue
[2024-02-16T09:12:59.809+0000] {logging_mixin.py:188} INFO - [2024-02-16T09:12:59.808+0000] {dagbag.py:538} INFO - Filling up the DagBag from /home/pkn/e-commerce_data_pipeline/dags/etl_dag.py
[2024-02-16T09:12:59.812+0000] {logging_mixin.py:188} INFO - [2024-02-16T09:12:59.812+0000] {dagbag.py:348} ERROR - Failed to import: /home/pkn/e-commerce_data_pipeline/dags/etl_dag.py
Traceback (most recent call last):
  File "/home/pkn/e-commerce_data_pipeline/venv/lib/python3.10/site-packages/airflow/models/dagbag.py", line 344, in parse
    loader.exec_module(new_module)
  File "<frozen importlib._bootstrap_external>", line 883, in exec_module
  File "<frozen importlib._bootstrap>", line 241, in _call_with_frames_removed
  File "/home/pkn/e-commerce_data_pipeline/dags/etl_dag.py", line 4, in <module>
    from ..scripts.imp_clean_trans_script import clean_transform_main
ImportError: attempted relative import with no known parent package
[2024-02-16T09:12:59.813+0000] {processor.py:842} WARNING - No viable dags retrieved from /home/pkn/e-commerce_data_pipeline/dags/etl_dag.py
[2024-02-16T09:12:59.843+0000] {processor.py:183} INFO - Processing /home/pkn/e-commerce_data_pipeline/dags/etl_dag.py took 0.044 seconds
[2024-02-16T09:13:30.456+0000] {processor.py:161} INFO - Started process (PID=376183) to work on /home/pkn/e-commerce_data_pipeline/dags/etl_dag.py
[2024-02-16T09:13:30.457+0000] {processor.py:830} INFO - Processing file /home/pkn/e-commerce_data_pipeline/dags/etl_dag.py for tasks to queue
[2024-02-16T09:13:30.458+0000] {logging_mixin.py:188} INFO - [2024-02-16T09:13:30.458+0000] {dagbag.py:538} INFO - Filling up the DagBag from /home/pkn/e-commerce_data_pipeline/dags/etl_dag.py
[2024-02-16T09:13:30.460+0000] {logging_mixin.py:188} INFO - [2024-02-16T09:13:30.459+0000] {dagbag.py:348} ERROR - Failed to import: /home/pkn/e-commerce_data_pipeline/dags/etl_dag.py
Traceback (most recent call last):
  File "/home/pkn/e-commerce_data_pipeline/venv/lib/python3.10/site-packages/airflow/models/dagbag.py", line 344, in parse
    loader.exec_module(new_module)
  File "<frozen importlib._bootstrap_external>", line 883, in exec_module
  File "<frozen importlib._bootstrap>", line 241, in _call_with_frames_removed
  File "/home/pkn/e-commerce_data_pipeline/dags/etl_dag.py", line 4, in <module>
    from ..scripts.imp_clean_trans_script import clean_transform_main
ImportError: attempted relative import with no known parent package
[2024-02-16T09:13:30.460+0000] {processor.py:842} WARNING - No viable dags retrieved from /home/pkn/e-commerce_data_pipeline/dags/etl_dag.py
[2024-02-16T09:13:30.492+0000] {processor.py:183} INFO - Processing /home/pkn/e-commerce_data_pipeline/dags/etl_dag.py took 0.041 seconds
[2024-02-16T09:14:00.704+0000] {processor.py:161} INFO - Started process (PID=376402) to work on /home/pkn/e-commerce_data_pipeline/dags/etl_dag.py
[2024-02-16T09:14:00.706+0000] {processor.py:830} INFO - Processing file /home/pkn/e-commerce_data_pipeline/dags/etl_dag.py for tasks to queue
[2024-02-16T09:14:00.707+0000] {logging_mixin.py:188} INFO - [2024-02-16T09:14:00.707+0000] {dagbag.py:538} INFO - Filling up the DagBag from /home/pkn/e-commerce_data_pipeline/dags/etl_dag.py
[2024-02-16T09:14:00.709+0000] {logging_mixin.py:188} INFO - [2024-02-16T09:14:00.709+0000] {dagbag.py:348} ERROR - Failed to import: /home/pkn/e-commerce_data_pipeline/dags/etl_dag.py
Traceback (most recent call last):
  File "/home/pkn/e-commerce_data_pipeline/venv/lib/python3.10/site-packages/airflow/models/dagbag.py", line 344, in parse
    loader.exec_module(new_module)
  File "<frozen importlib._bootstrap_external>", line 883, in exec_module
  File "<frozen importlib._bootstrap>", line 241, in _call_with_frames_removed
  File "/home/pkn/e-commerce_data_pipeline/dags/etl_dag.py", line 4, in <module>
    from ..scripts.imp_clean_trans_script import clean_transform_main
ImportError: attempted relative import with no known parent package
[2024-02-16T09:14:00.709+0000] {processor.py:842} WARNING - No viable dags retrieved from /home/pkn/e-commerce_data_pipeline/dags/etl_dag.py
[2024-02-16T09:14:00.734+0000] {processor.py:183} INFO - Processing /home/pkn/e-commerce_data_pipeline/dags/etl_dag.py took 0.035 seconds
[2024-02-16T09:14:31.420+0000] {processor.py:161} INFO - Started process (PID=376686) to work on /home/pkn/e-commerce_data_pipeline/dags/etl_dag.py
[2024-02-16T09:14:31.422+0000] {processor.py:830} INFO - Processing file /home/pkn/e-commerce_data_pipeline/dags/etl_dag.py for tasks to queue
[2024-02-16T09:14:31.423+0000] {logging_mixin.py:188} INFO - [2024-02-16T09:14:31.423+0000] {dagbag.py:538} INFO - Filling up the DagBag from /home/pkn/e-commerce_data_pipeline/dags/etl_dag.py
[2024-02-16T09:14:31.426+0000] {logging_mixin.py:188} INFO - [2024-02-16T09:14:31.426+0000] {dagbag.py:348} ERROR - Failed to import: /home/pkn/e-commerce_data_pipeline/dags/etl_dag.py
Traceback (most recent call last):
  File "/home/pkn/e-commerce_data_pipeline/venv/lib/python3.10/site-packages/airflow/models/dagbag.py", line 344, in parse
    loader.exec_module(new_module)
  File "<frozen importlib._bootstrap_external>", line 883, in exec_module
  File "<frozen importlib._bootstrap>", line 241, in _call_with_frames_removed
  File "/home/pkn/e-commerce_data_pipeline/dags/etl_dag.py", line 4, in <module>
    from ..scripts.imp_clean_trans_script import clean_transform_main
ImportError: attempted relative import with no known parent package
[2024-02-16T09:14:31.427+0000] {processor.py:842} WARNING - No viable dags retrieved from /home/pkn/e-commerce_data_pipeline/dags/etl_dag.py
[2024-02-16T09:14:31.470+0000] {processor.py:183} INFO - Processing /home/pkn/e-commerce_data_pipeline/dags/etl_dag.py took 0.056 seconds
[2024-02-16T09:15:01.546+0000] {processor.py:161} INFO - Started process (PID=377045) to work on /home/pkn/e-commerce_data_pipeline/dags/etl_dag.py
[2024-02-16T09:15:01.547+0000] {processor.py:830} INFO - Processing file /home/pkn/e-commerce_data_pipeline/dags/etl_dag.py for tasks to queue
[2024-02-16T09:15:01.548+0000] {logging_mixin.py:188} INFO - [2024-02-16T09:15:01.548+0000] {dagbag.py:538} INFO - Filling up the DagBag from /home/pkn/e-commerce_data_pipeline/dags/etl_dag.py
[2024-02-16T09:15:01.552+0000] {logging_mixin.py:188} INFO - [2024-02-16T09:15:01.551+0000] {dagbag.py:348} ERROR - Failed to import: /home/pkn/e-commerce_data_pipeline/dags/etl_dag.py
Traceback (most recent call last):
  File "/home/pkn/e-commerce_data_pipeline/venv/lib/python3.10/site-packages/airflow/models/dagbag.py", line 344, in parse
    loader.exec_module(new_module)
  File "<frozen importlib._bootstrap_external>", line 883, in exec_module
  File "<frozen importlib._bootstrap>", line 241, in _call_with_frames_removed
  File "/home/pkn/e-commerce_data_pipeline/dags/etl_dag.py", line 4, in <module>
    from ..scripts.imp_clean_trans_script import clean_transform_main
ImportError: attempted relative import with no known parent package
[2024-02-16T09:15:01.552+0000] {processor.py:842} WARNING - No viable dags retrieved from /home/pkn/e-commerce_data_pipeline/dags/etl_dag.py
[2024-02-16T09:15:01.589+0000] {processor.py:183} INFO - Processing /home/pkn/e-commerce_data_pipeline/dags/etl_dag.py took 0.049 seconds
[2024-02-16T09:15:31.719+0000] {processor.py:161} INFO - Started process (PID=377365) to work on /home/pkn/e-commerce_data_pipeline/dags/etl_dag.py
[2024-02-16T09:15:31.721+0000] {processor.py:830} INFO - Processing file /home/pkn/e-commerce_data_pipeline/dags/etl_dag.py for tasks to queue
[2024-02-16T09:15:31.724+0000] {logging_mixin.py:188} INFO - [2024-02-16T09:15:31.723+0000] {dagbag.py:538} INFO - Filling up the DagBag from /home/pkn/e-commerce_data_pipeline/dags/etl_dag.py
[2024-02-16T09:15:31.731+0000] {logging_mixin.py:188} INFO - [2024-02-16T09:15:31.730+0000] {dagbag.py:348} ERROR - Failed to import: /home/pkn/e-commerce_data_pipeline/dags/etl_dag.py
Traceback (most recent call last):
  File "/home/pkn/e-commerce_data_pipeline/venv/lib/python3.10/site-packages/airflow/models/dagbag.py", line 344, in parse
    loader.exec_module(new_module)
  File "<frozen importlib._bootstrap_external>", line 883, in exec_module
  File "<frozen importlib._bootstrap>", line 241, in _call_with_frames_removed
  File "/home/pkn/e-commerce_data_pipeline/dags/etl_dag.py", line 4, in <module>
    from ..scripts.imp_clean_trans_script import clean_transform_main
ImportError: attempted relative import with no known parent package
[2024-02-16T09:15:31.731+0000] {processor.py:842} WARNING - No viable dags retrieved from /home/pkn/e-commerce_data_pipeline/dags/etl_dag.py
[2024-02-16T09:15:31.767+0000] {processor.py:183} INFO - Processing /home/pkn/e-commerce_data_pipeline/dags/etl_dag.py took 0.054 seconds
[2024-02-16T09:15:47.620+0000] {processor.py:161} INFO - Started process (PID=377549) to work on /home/pkn/e-commerce_data_pipeline/dags/etl_dag.py
[2024-02-16T09:15:47.621+0000] {processor.py:830} INFO - Processing file /home/pkn/e-commerce_data_pipeline/dags/etl_dag.py for tasks to queue
[2024-02-16T09:15:47.623+0000] {logging_mixin.py:188} INFO - [2024-02-16T09:15:47.623+0000] {dagbag.py:538} INFO - Filling up the DagBag from /home/pkn/e-commerce_data_pipeline/dags/etl_dag.py
[2024-02-16T09:15:47.630+0000] {logging_mixin.py:188} INFO - [2024-02-16T09:15:47.629+0000] {dagbag.py:348} ERROR - Failed to import: /home/pkn/e-commerce_data_pipeline/dags/etl_dag.py
Traceback (most recent call last):
  File "/home/pkn/e-commerce_data_pipeline/venv/lib/python3.10/site-packages/airflow/models/dagbag.py", line 344, in parse
    loader.exec_module(new_module)
  File "<frozen importlib._bootstrap_external>", line 883, in exec_module
  File "<frozen importlib._bootstrap>", line 241, in _call_with_frames_removed
  File "/home/pkn/e-commerce_data_pipeline/dags/etl_dag.py", line 4, in <module>
    from ..scripts.imp_clean_trans_script import clean_transform_main
ImportError: attempted relative import with no known parent package
[2024-02-16T09:15:47.630+0000] {processor.py:842} WARNING - No viable dags retrieved from /home/pkn/e-commerce_data_pipeline/dags/etl_dag.py
[2024-02-16T09:15:47.656+0000] {processor.py:183} INFO - Processing /home/pkn/e-commerce_data_pipeline/dags/etl_dag.py took 0.043 seconds
[2024-02-16T09:16:02.042+0000] {processor.py:161} INFO - Started process (PID=377872) to work on /home/pkn/e-commerce_data_pipeline/dags/etl_dag.py
[2024-02-16T09:16:02.045+0000] {processor.py:830} INFO - Processing file /home/pkn/e-commerce_data_pipeline/dags/etl_dag.py for tasks to queue
[2024-02-16T09:16:02.046+0000] {logging_mixin.py:188} INFO - [2024-02-16T09:16:02.045+0000] {dagbag.py:538} INFO - Filling up the DagBag from /home/pkn/e-commerce_data_pipeline/dags/etl_dag.py
[2024-02-16T09:16:02.049+0000] {logging_mixin.py:188} INFO - [2024-02-16T09:16:02.048+0000] {dagbag.py:348} ERROR - Failed to import: /home/pkn/e-commerce_data_pipeline/dags/etl_dag.py
Traceback (most recent call last):
  File "/home/pkn/e-commerce_data_pipeline/venv/lib/python3.10/site-packages/airflow/models/dagbag.py", line 344, in parse
    loader.exec_module(new_module)
  File "<frozen importlib._bootstrap_external>", line 883, in exec_module
  File "<frozen importlib._bootstrap>", line 241, in _call_with_frames_removed
  File "/home/pkn/e-commerce_data_pipeline/dags/etl_dag.py", line 4, in <module>
    from ..scripts.imp_clean_trans_script import clean_transform_main
ImportError: attempted relative import with no known parent package
[2024-02-16T09:16:02.050+0000] {processor.py:842} WARNING - No viable dags retrieved from /home/pkn/e-commerce_data_pipeline/dags/etl_dag.py
[2024-02-16T09:16:02.086+0000] {processor.py:183} INFO - Processing /home/pkn/e-commerce_data_pipeline/dags/etl_dag.py took 0.050 seconds
[2024-02-16T09:16:32.614+0000] {processor.py:161} INFO - Started process (PID=378151) to work on /home/pkn/e-commerce_data_pipeline/dags/etl_dag.py
[2024-02-16T09:16:32.615+0000] {processor.py:830} INFO - Processing file /home/pkn/e-commerce_data_pipeline/dags/etl_dag.py for tasks to queue
[2024-02-16T09:16:32.617+0000] {logging_mixin.py:188} INFO - [2024-02-16T09:16:32.616+0000] {dagbag.py:538} INFO - Filling up the DagBag from /home/pkn/e-commerce_data_pipeline/dags/etl_dag.py
[2024-02-16T09:16:32.621+0000] {logging_mixin.py:188} INFO - [2024-02-16T09:16:32.620+0000] {dagbag.py:348} ERROR - Failed to import: /home/pkn/e-commerce_data_pipeline/dags/etl_dag.py
Traceback (most recent call last):
  File "/home/pkn/e-commerce_data_pipeline/venv/lib/python3.10/site-packages/airflow/models/dagbag.py", line 344, in parse
    loader.exec_module(new_module)
  File "<frozen importlib._bootstrap_external>", line 883, in exec_module
  File "<frozen importlib._bootstrap>", line 241, in _call_with_frames_removed
  File "/home/pkn/e-commerce_data_pipeline/dags/etl_dag.py", line 4, in <module>
    from ..scripts.imp_clean_trans_script import clean_transform_main
ImportError: attempted relative import with no known parent package
[2024-02-16T09:16:32.621+0000] {processor.py:842} WARNING - No viable dags retrieved from /home/pkn/e-commerce_data_pipeline/dags/etl_dag.py
[2024-02-16T09:16:32.653+0000] {processor.py:183} INFO - Processing /home/pkn/e-commerce_data_pipeline/dags/etl_dag.py took 0.044 seconds
[2024-02-16T09:17:03.662+0000] {processor.py:161} INFO - Started process (PID=378419) to work on /home/pkn/e-commerce_data_pipeline/dags/etl_dag.py
[2024-02-16T09:17:03.664+0000] {processor.py:830} INFO - Processing file /home/pkn/e-commerce_data_pipeline/dags/etl_dag.py for tasks to queue
[2024-02-16T09:17:03.665+0000] {logging_mixin.py:188} INFO - [2024-02-16T09:17:03.665+0000] {dagbag.py:538} INFO - Filling up the DagBag from /home/pkn/e-commerce_data_pipeline/dags/etl_dag.py
[2024-02-16T09:17:03.669+0000] {logging_mixin.py:188} INFO - [2024-02-16T09:17:03.668+0000] {dagbag.py:348} ERROR - Failed to import: /home/pkn/e-commerce_data_pipeline/dags/etl_dag.py
Traceback (most recent call last):
  File "/home/pkn/e-commerce_data_pipeline/venv/lib/python3.10/site-packages/airflow/models/dagbag.py", line 344, in parse
    loader.exec_module(new_module)
  File "<frozen importlib._bootstrap_external>", line 883, in exec_module
  File "<frozen importlib._bootstrap>", line 241, in _call_with_frames_removed
  File "/home/pkn/e-commerce_data_pipeline/dags/etl_dag.py", line 4, in <module>
    from ..scripts.imp_clean_trans_script import clean_transform_main
ImportError: attempted relative import with no known parent package
[2024-02-16T09:17:03.670+0000] {processor.py:842} WARNING - No viable dags retrieved from /home/pkn/e-commerce_data_pipeline/dags/etl_dag.py
[2024-02-16T09:17:03.699+0000] {processor.py:183} INFO - Processing /home/pkn/e-commerce_data_pipeline/dags/etl_dag.py took 0.043 seconds
[2024-02-16T09:17:33.796+0000] {processor.py:161} INFO - Started process (PID=378614) to work on /home/pkn/e-commerce_data_pipeline/dags/etl_dag.py
[2024-02-16T09:17:33.797+0000] {processor.py:830} INFO - Processing file /home/pkn/e-commerce_data_pipeline/dags/etl_dag.py for tasks to queue
[2024-02-16T09:17:33.798+0000] {logging_mixin.py:188} INFO - [2024-02-16T09:17:33.798+0000] {dagbag.py:538} INFO - Filling up the DagBag from /home/pkn/e-commerce_data_pipeline/dags/etl_dag.py
[2024-02-16T09:17:33.802+0000] {logging_mixin.py:188} INFO - [2024-02-16T09:17:33.801+0000] {dagbag.py:348} ERROR - Failed to import: /home/pkn/e-commerce_data_pipeline/dags/etl_dag.py
Traceback (most recent call last):
  File "/home/pkn/e-commerce_data_pipeline/venv/lib/python3.10/site-packages/airflow/models/dagbag.py", line 344, in parse
    loader.exec_module(new_module)
  File "<frozen importlib._bootstrap_external>", line 883, in exec_module
  File "<frozen importlib._bootstrap>", line 241, in _call_with_frames_removed
  File "/home/pkn/e-commerce_data_pipeline/dags/etl_dag.py", line 4, in <module>
    from ..scripts.imp_clean_trans_script import clean_transform_main
ImportError: attempted relative import with no known parent package
[2024-02-16T09:17:33.802+0000] {processor.py:842} WARNING - No viable dags retrieved from /home/pkn/e-commerce_data_pipeline/dags/etl_dag.py
[2024-02-16T09:17:33.838+0000] {processor.py:183} INFO - Processing /home/pkn/e-commerce_data_pipeline/dags/etl_dag.py took 0.048 seconds
[2024-02-16T09:18:03.904+0000] {processor.py:161} INFO - Started process (PID=379026) to work on /home/pkn/e-commerce_data_pipeline/dags/etl_dag.py
[2024-02-16T09:18:03.906+0000] {processor.py:830} INFO - Processing file /home/pkn/e-commerce_data_pipeline/dags/etl_dag.py for tasks to queue
[2024-02-16T09:18:03.906+0000] {logging_mixin.py:188} INFO - [2024-02-16T09:18:03.906+0000] {dagbag.py:538} INFO - Filling up the DagBag from /home/pkn/e-commerce_data_pipeline/dags/etl_dag.py
[2024-02-16T09:18:03.909+0000] {logging_mixin.py:188} INFO - [2024-02-16T09:18:03.909+0000] {dagbag.py:348} ERROR - Failed to import: /home/pkn/e-commerce_data_pipeline/dags/etl_dag.py
Traceback (most recent call last):
  File "/home/pkn/e-commerce_data_pipeline/venv/lib/python3.10/site-packages/airflow/models/dagbag.py", line 344, in parse
    loader.exec_module(new_module)
  File "<frozen importlib._bootstrap_external>", line 883, in exec_module
  File "<frozen importlib._bootstrap>", line 241, in _call_with_frames_removed
  File "/home/pkn/e-commerce_data_pipeline/dags/etl_dag.py", line 4, in <module>
    from ..scripts.imp_clean_trans_script import clean_transform_main
ImportError: attempted relative import with no known parent package
[2024-02-16T09:18:03.910+0000] {processor.py:842} WARNING - No viable dags retrieved from /home/pkn/e-commerce_data_pipeline/dags/etl_dag.py
[2024-02-16T09:18:03.943+0000] {processor.py:183} INFO - Processing /home/pkn/e-commerce_data_pipeline/dags/etl_dag.py took 0.044 seconds
[2024-02-16T09:18:34.503+0000] {processor.py:161} INFO - Started process (PID=379355) to work on /home/pkn/e-commerce_data_pipeline/dags/etl_dag.py
[2024-02-16T09:18:34.504+0000] {processor.py:830} INFO - Processing file /home/pkn/e-commerce_data_pipeline/dags/etl_dag.py for tasks to queue
[2024-02-16T09:18:34.505+0000] {logging_mixin.py:188} INFO - [2024-02-16T09:18:34.505+0000] {dagbag.py:538} INFO - Filling up the DagBag from /home/pkn/e-commerce_data_pipeline/dags/etl_dag.py
[2024-02-16T09:18:34.508+0000] {logging_mixin.py:188} INFO - [2024-02-16T09:18:34.507+0000] {dagbag.py:348} ERROR - Failed to import: /home/pkn/e-commerce_data_pipeline/dags/etl_dag.py
Traceback (most recent call last):
  File "/home/pkn/e-commerce_data_pipeline/venv/lib/python3.10/site-packages/airflow/models/dagbag.py", line 344, in parse
    loader.exec_module(new_module)
  File "<frozen importlib._bootstrap_external>", line 883, in exec_module
  File "<frozen importlib._bootstrap>", line 241, in _call_with_frames_removed
  File "/home/pkn/e-commerce_data_pipeline/dags/etl_dag.py", line 4, in <module>
    from ..scripts.imp_clean_trans_script import clean_transform_main
ImportError: attempted relative import with no known parent package
[2024-02-16T09:18:34.508+0000] {processor.py:842} WARNING - No viable dags retrieved from /home/pkn/e-commerce_data_pipeline/dags/etl_dag.py
[2024-02-16T09:18:34.540+0000] {processor.py:183} INFO - Processing /home/pkn/e-commerce_data_pipeline/dags/etl_dag.py took 0.043 seconds
[2024-02-16T09:19:05.501+0000] {processor.py:161} INFO - Started process (PID=379642) to work on /home/pkn/e-commerce_data_pipeline/dags/etl_dag.py
[2024-02-16T09:19:05.502+0000] {processor.py:830} INFO - Processing file /home/pkn/e-commerce_data_pipeline/dags/etl_dag.py for tasks to queue
[2024-02-16T09:19:05.503+0000] {logging_mixin.py:188} INFO - [2024-02-16T09:19:05.503+0000] {dagbag.py:538} INFO - Filling up the DagBag from /home/pkn/e-commerce_data_pipeline/dags/etl_dag.py
[2024-02-16T09:19:05.506+0000] {logging_mixin.py:188} INFO - [2024-02-16T09:19:05.505+0000] {dagbag.py:348} ERROR - Failed to import: /home/pkn/e-commerce_data_pipeline/dags/etl_dag.py
Traceback (most recent call last):
  File "/home/pkn/e-commerce_data_pipeline/venv/lib/python3.10/site-packages/airflow/models/dagbag.py", line 344, in parse
    loader.exec_module(new_module)
  File "<frozen importlib._bootstrap_external>", line 883, in exec_module
  File "<frozen importlib._bootstrap>", line 241, in _call_with_frames_removed
  File "/home/pkn/e-commerce_data_pipeline/dags/etl_dag.py", line 4, in <module>
    from ..scripts.imp_clean_trans_script import clean_transform_main
ImportError: attempted relative import with no known parent package
[2024-02-16T09:19:05.507+0000] {processor.py:842} WARNING - No viable dags retrieved from /home/pkn/e-commerce_data_pipeline/dags/etl_dag.py
[2024-02-16T09:19:05.537+0000] {processor.py:183} INFO - Processing /home/pkn/e-commerce_data_pipeline/dags/etl_dag.py took 0.042 seconds
[2024-02-16T09:19:35.672+0000] {processor.py:161} INFO - Started process (PID=379998) to work on /home/pkn/e-commerce_data_pipeline/dags/etl_dag.py
[2024-02-16T09:19:35.674+0000] {processor.py:830} INFO - Processing file /home/pkn/e-commerce_data_pipeline/dags/etl_dag.py for tasks to queue
[2024-02-16T09:19:35.675+0000] {logging_mixin.py:188} INFO - [2024-02-16T09:19:35.675+0000] {dagbag.py:538} INFO - Filling up the DagBag from /home/pkn/e-commerce_data_pipeline/dags/etl_dag.py
[2024-02-16T09:19:35.678+0000] {logging_mixin.py:188} INFO - [2024-02-16T09:19:35.677+0000] {dagbag.py:348} ERROR - Failed to import: /home/pkn/e-commerce_data_pipeline/dags/etl_dag.py
Traceback (most recent call last):
  File "/home/pkn/e-commerce_data_pipeline/venv/lib/python3.10/site-packages/airflow/models/dagbag.py", line 344, in parse
    loader.exec_module(new_module)
  File "<frozen importlib._bootstrap_external>", line 883, in exec_module
  File "<frozen importlib._bootstrap>", line 241, in _call_with_frames_removed
  File "/home/pkn/e-commerce_data_pipeline/dags/etl_dag.py", line 4, in <module>
    from ..scripts.imp_clean_trans_script import clean_transform_main
ImportError: attempted relative import with no known parent package
[2024-02-16T09:19:35.679+0000] {processor.py:842} WARNING - No viable dags retrieved from /home/pkn/e-commerce_data_pipeline/dags/etl_dag.py
[2024-02-16T09:19:35.713+0000] {processor.py:183} INFO - Processing /home/pkn/e-commerce_data_pipeline/dags/etl_dag.py took 0.046 seconds
[2024-02-16T09:20:06.482+0000] {processor.py:161} INFO - Started process (PID=380399) to work on /home/pkn/e-commerce_data_pipeline/dags/etl_dag.py
[2024-02-16T09:20:06.483+0000] {processor.py:830} INFO - Processing file /home/pkn/e-commerce_data_pipeline/dags/etl_dag.py for tasks to queue
[2024-02-16T09:20:06.484+0000] {logging_mixin.py:188} INFO - [2024-02-16T09:20:06.484+0000] {dagbag.py:538} INFO - Filling up the DagBag from /home/pkn/e-commerce_data_pipeline/dags/etl_dag.py
[2024-02-16T09:20:06.488+0000] {logging_mixin.py:188} INFO - [2024-02-16T09:20:06.487+0000] {dagbag.py:348} ERROR - Failed to import: /home/pkn/e-commerce_data_pipeline/dags/etl_dag.py
Traceback (most recent call last):
  File "/home/pkn/e-commerce_data_pipeline/venv/lib/python3.10/site-packages/airflow/models/dagbag.py", line 344, in parse
    loader.exec_module(new_module)
  File "<frozen importlib._bootstrap_external>", line 883, in exec_module
  File "<frozen importlib._bootstrap>", line 241, in _call_with_frames_removed
  File "/home/pkn/e-commerce_data_pipeline/dags/etl_dag.py", line 4, in <module>
    from ..scripts.imp_clean_trans_script import clean_transform_main
ImportError: attempted relative import with no known parent package
[2024-02-16T09:20:06.488+0000] {processor.py:842} WARNING - No viable dags retrieved from /home/pkn/e-commerce_data_pipeline/dags/etl_dag.py
[2024-02-16T09:20:06.525+0000] {processor.py:183} INFO - Processing /home/pkn/e-commerce_data_pipeline/dags/etl_dag.py took 0.048 seconds
[2024-02-16T09:20:37.454+0000] {processor.py:161} INFO - Started process (PID=380815) to work on /home/pkn/e-commerce_data_pipeline/dags/etl_dag.py
[2024-02-16T09:20:37.456+0000] {processor.py:830} INFO - Processing file /home/pkn/e-commerce_data_pipeline/dags/etl_dag.py for tasks to queue
[2024-02-16T09:20:37.457+0000] {logging_mixin.py:188} INFO - [2024-02-16T09:20:37.457+0000] {dagbag.py:538} INFO - Filling up the DagBag from /home/pkn/e-commerce_data_pipeline/dags/etl_dag.py
[2024-02-16T09:20:37.461+0000] {logging_mixin.py:188} INFO - [2024-02-16T09:20:37.460+0000] {dagbag.py:348} ERROR - Failed to import: /home/pkn/e-commerce_data_pipeline/dags/etl_dag.py
Traceback (most recent call last):
  File "/home/pkn/e-commerce_data_pipeline/venv/lib/python3.10/site-packages/airflow/models/dagbag.py", line 344, in parse
    loader.exec_module(new_module)
  File "<frozen importlib._bootstrap_external>", line 883, in exec_module
  File "<frozen importlib._bootstrap>", line 241, in _call_with_frames_removed
  File "/home/pkn/e-commerce_data_pipeline/dags/etl_dag.py", line 4, in <module>
    from ..scripts.imp_clean_trans_script import clean_transform_main
ImportError: attempted relative import with no known parent package
[2024-02-16T09:20:37.461+0000] {processor.py:842} WARNING - No viable dags retrieved from /home/pkn/e-commerce_data_pipeline/dags/etl_dag.py
[2024-02-16T09:20:37.495+0000] {processor.py:183} INFO - Processing /home/pkn/e-commerce_data_pipeline/dags/etl_dag.py took 0.046 seconds
[2024-02-16T09:20:54.259+0000] {processor.py:161} INFO - Started process (PID=381008) to work on /home/pkn/e-commerce_data_pipeline/dags/etl_dag.py
[2024-02-16T09:20:54.260+0000] {processor.py:830} INFO - Processing file /home/pkn/e-commerce_data_pipeline/dags/etl_dag.py for tasks to queue
[2024-02-16T09:20:54.261+0000] {logging_mixin.py:188} INFO - [2024-02-16T09:20:54.261+0000] {dagbag.py:538} INFO - Filling up the DagBag from /home/pkn/e-commerce_data_pipeline/dags/etl_dag.py
[2024-02-16T09:20:54.269+0000] {logging_mixin.py:188} INFO - [2024-02-16T09:20:54.268+0000] {dagbag.py:348} ERROR - Failed to import: /home/pkn/e-commerce_data_pipeline/dags/etl_dag.py
Traceback (most recent call last):
  File "/home/pkn/e-commerce_data_pipeline/venv/lib/python3.10/site-packages/airflow/models/dagbag.py", line 344, in parse
    loader.exec_module(new_module)
  File "<frozen importlib._bootstrap_external>", line 883, in exec_module
  File "<frozen importlib._bootstrap>", line 241, in _call_with_frames_removed
  File "/home/pkn/e-commerce_data_pipeline/dags/etl_dag.py", line 4, in <module>
    from ..scripts.imp_clean_trans_script import clean_transform_main
ImportError: attempted relative import with no known parent package
[2024-02-16T09:20:54.269+0000] {processor.py:842} WARNING - No viable dags retrieved from /home/pkn/e-commerce_data_pipeline/dags/etl_dag.py
[2024-02-16T09:20:54.298+0000] {processor.py:183} INFO - Processing /home/pkn/e-commerce_data_pipeline/dags/etl_dag.py took 0.045 seconds
[2024-02-16T09:21:08.496+0000] {processor.py:161} INFO - Started process (PID=381295) to work on /home/pkn/e-commerce_data_pipeline/dags/etl_dag.py
[2024-02-16T09:21:08.497+0000] {processor.py:830} INFO - Processing file /home/pkn/e-commerce_data_pipeline/dags/etl_dag.py for tasks to queue
[2024-02-16T09:21:08.498+0000] {logging_mixin.py:188} INFO - [2024-02-16T09:21:08.498+0000] {dagbag.py:538} INFO - Filling up the DagBag from /home/pkn/e-commerce_data_pipeline/dags/etl_dag.py
[2024-02-16T09:21:08.502+0000] {logging_mixin.py:188} INFO - [2024-02-16T09:21:08.501+0000] {dagbag.py:348} ERROR - Failed to import: /home/pkn/e-commerce_data_pipeline/dags/etl_dag.py
Traceback (most recent call last):
  File "/home/pkn/e-commerce_data_pipeline/venv/lib/python3.10/site-packages/airflow/models/dagbag.py", line 344, in parse
    loader.exec_module(new_module)
  File "<frozen importlib._bootstrap_external>", line 883, in exec_module
  File "<frozen importlib._bootstrap>", line 241, in _call_with_frames_removed
  File "/home/pkn/e-commerce_data_pipeline/dags/etl_dag.py", line 4, in <module>
    from ..scripts.imp_clean_trans_script import clean_transform_main
ImportError: attempted relative import with no known parent package
[2024-02-16T09:21:08.502+0000] {processor.py:842} WARNING - No viable dags retrieved from /home/pkn/e-commerce_data_pipeline/dags/etl_dag.py
[2024-02-16T09:21:08.536+0000] {processor.py:183} INFO - Processing /home/pkn/e-commerce_data_pipeline/dags/etl_dag.py took 0.044 seconds
[2024-02-16T09:21:25.273+0000] {processor.py:161} INFO - Started process (PID=381474) to work on /home/pkn/e-commerce_data_pipeline/dags/etl_dag.py
[2024-02-16T09:21:25.275+0000] {processor.py:830} INFO - Processing file /home/pkn/e-commerce_data_pipeline/dags/etl_dag.py for tasks to queue
[2024-02-16T09:21:25.275+0000] {logging_mixin.py:188} INFO - [2024-02-16T09:21:25.275+0000] {dagbag.py:538} INFO - Filling up the DagBag from /home/pkn/e-commerce_data_pipeline/dags/etl_dag.py
[2024-02-16T09:21:25.278+0000] {logging_mixin.py:188} INFO - [2024-02-16T09:21:25.278+0000] {dagbag.py:348} ERROR - Failed to import: /home/pkn/e-commerce_data_pipeline/dags/etl_dag.py
Traceback (most recent call last):
  File "/home/pkn/e-commerce_data_pipeline/venv/lib/python3.10/site-packages/airflow/models/dagbag.py", line 344, in parse
    loader.exec_module(new_module)
  File "<frozen importlib._bootstrap_external>", line 883, in exec_module
  File "<frozen importlib._bootstrap>", line 241, in _call_with_frames_removed
  File "/home/pkn/e-commerce_data_pipeline/dags/etl_dag.py", line 4, in <module>
    from ..scripts.imp_clean_trans_script import clean_transform_main
ImportError: attempted relative import with no known parent package
[2024-02-16T09:21:25.279+0000] {processor.py:842} WARNING - No viable dags retrieved from /home/pkn/e-commerce_data_pipeline/dags/etl_dag.py
[2024-02-16T09:21:25.305+0000] {processor.py:183} INFO - Processing /home/pkn/e-commerce_data_pipeline/dags/etl_dag.py took 0.036 seconds
[2024-02-16T09:21:39.334+0000] {processor.py:161} INFO - Started process (PID=381783) to work on /home/pkn/e-commerce_data_pipeline/dags/etl_dag.py
[2024-02-16T09:21:39.335+0000] {processor.py:830} INFO - Processing file /home/pkn/e-commerce_data_pipeline/dags/etl_dag.py for tasks to queue
[2024-02-16T09:21:39.336+0000] {logging_mixin.py:188} INFO - [2024-02-16T09:21:39.336+0000] {dagbag.py:538} INFO - Filling up the DagBag from /home/pkn/e-commerce_data_pipeline/dags/etl_dag.py
[2024-02-16T09:21:39.339+0000] {logging_mixin.py:188} INFO - [2024-02-16T09:21:39.338+0000] {dagbag.py:348} ERROR - Failed to import: /home/pkn/e-commerce_data_pipeline/dags/etl_dag.py
Traceback (most recent call last):
  File "/home/pkn/e-commerce_data_pipeline/venv/lib/python3.10/site-packages/airflow/models/dagbag.py", line 344, in parse
    loader.exec_module(new_module)
  File "<frozen importlib._bootstrap_external>", line 883, in exec_module
  File "<frozen importlib._bootstrap>", line 241, in _call_with_frames_removed
  File "/home/pkn/e-commerce_data_pipeline/dags/etl_dag.py", line 4, in <module>
    from ..scripts.imp_clean_trans_script import clean_transform_main
ImportError: attempted relative import with no known parent package
[2024-02-16T09:21:39.340+0000] {processor.py:842} WARNING - No viable dags retrieved from /home/pkn/e-commerce_data_pipeline/dags/etl_dag.py
[2024-02-16T09:21:39.366+0000] {processor.py:183} INFO - Processing /home/pkn/e-commerce_data_pipeline/dags/etl_dag.py took 0.037 seconds
[2024-02-16T09:21:55.335+0000] {processor.py:161} INFO - Started process (PID=381934) to work on /home/pkn/e-commerce_data_pipeline/dags/etl_dag.py
[2024-02-16T09:21:55.336+0000] {processor.py:830} INFO - Processing file /home/pkn/e-commerce_data_pipeline/dags/etl_dag.py for tasks to queue
[2024-02-16T09:21:55.337+0000] {logging_mixin.py:188} INFO - [2024-02-16T09:21:55.336+0000] {dagbag.py:538} INFO - Filling up the DagBag from /home/pkn/e-commerce_data_pipeline/dags/etl_dag.py
[2024-02-16T09:21:55.339+0000] {logging_mixin.py:188} INFO - [2024-02-16T09:21:55.339+0000] {dagbag.py:348} ERROR - Failed to import: /home/pkn/e-commerce_data_pipeline/dags/etl_dag.py
Traceback (most recent call last):
  File "/home/pkn/e-commerce_data_pipeline/venv/lib/python3.10/site-packages/airflow/models/dagbag.py", line 344, in parse
    loader.exec_module(new_module)
  File "<frozen importlib._bootstrap_external>", line 883, in exec_module
  File "<frozen importlib._bootstrap>", line 241, in _call_with_frames_removed
  File "/home/pkn/e-commerce_data_pipeline/dags/etl_dag.py", line 4, in <module>
    from ..scripts.imp_clean_trans_script import clean_transform_main
ImportError: attempted relative import with no known parent package
[2024-02-16T09:21:55.340+0000] {processor.py:842} WARNING - No viable dags retrieved from /home/pkn/e-commerce_data_pipeline/dags/etl_dag.py
[2024-02-16T09:21:55.369+0000] {processor.py:183} INFO - Processing /home/pkn/e-commerce_data_pipeline/dags/etl_dag.py took 0.038 seconds
[2024-02-16T09:22:26.335+0000] {processor.py:161} INFO - Started process (PID=382131) to work on /home/pkn/e-commerce_data_pipeline/dags/etl_dag.py
[2024-02-16T09:22:26.336+0000] {processor.py:830} INFO - Processing file /home/pkn/e-commerce_data_pipeline/dags/etl_dag.py for tasks to queue
[2024-02-16T09:22:26.337+0000] {logging_mixin.py:188} INFO - [2024-02-16T09:22:26.337+0000] {dagbag.py:538} INFO - Filling up the DagBag from /home/pkn/e-commerce_data_pipeline/dags/etl_dag.py
[2024-02-16T09:22:26.340+0000] {logging_mixin.py:188} INFO - [2024-02-16T09:22:26.339+0000] {dagbag.py:348} ERROR - Failed to import: /home/pkn/e-commerce_data_pipeline/dags/etl_dag.py
Traceback (most recent call last):
  File "/home/pkn/e-commerce_data_pipeline/venv/lib/python3.10/site-packages/airflow/models/dagbag.py", line 344, in parse
    loader.exec_module(new_module)
  File "<frozen importlib._bootstrap_external>", line 883, in exec_module
  File "<frozen importlib._bootstrap>", line 241, in _call_with_frames_removed
  File "/home/pkn/e-commerce_data_pipeline/dags/etl_dag.py", line 4, in <module>
    from ..scripts.imp_clean_trans_script import clean_transform_main
ImportError: attempted relative import with no known parent package
[2024-02-16T09:22:26.340+0000] {processor.py:842} WARNING - No viable dags retrieved from /home/pkn/e-commerce_data_pipeline/dags/etl_dag.py
[2024-02-16T09:22:26.370+0000] {processor.py:183} INFO - Processing /home/pkn/e-commerce_data_pipeline/dags/etl_dag.py took 0.041 seconds
[2024-02-16T09:22:56.658+0000] {processor.py:161} INFO - Started process (PID=382350) to work on /home/pkn/e-commerce_data_pipeline/dags/etl_dag.py
[2024-02-16T09:22:56.660+0000] {processor.py:830} INFO - Processing file /home/pkn/e-commerce_data_pipeline/dags/etl_dag.py for tasks to queue
[2024-02-16T09:22:56.661+0000] {logging_mixin.py:188} INFO - [2024-02-16T09:22:56.661+0000] {dagbag.py:538} INFO - Filling up the DagBag from /home/pkn/e-commerce_data_pipeline/dags/etl_dag.py
[2024-02-16T09:22:56.664+0000] {logging_mixin.py:188} INFO - [2024-02-16T09:22:56.664+0000] {dagbag.py:348} ERROR - Failed to import: /home/pkn/e-commerce_data_pipeline/dags/etl_dag.py
Traceback (most recent call last):
  File "/home/pkn/e-commerce_data_pipeline/venv/lib/python3.10/site-packages/airflow/models/dagbag.py", line 344, in parse
    loader.exec_module(new_module)
  File "<frozen importlib._bootstrap_external>", line 883, in exec_module
  File "<frozen importlib._bootstrap>", line 241, in _call_with_frames_removed
  File "/home/pkn/e-commerce_data_pipeline/dags/etl_dag.py", line 4, in <module>
    from ..scripts.imp_clean_trans_script import clean_transform_main
ImportError: attempted relative import with no known parent package
[2024-02-16T09:22:56.665+0000] {processor.py:842} WARNING - No viable dags retrieved from /home/pkn/e-commerce_data_pipeline/dags/etl_dag.py
[2024-02-16T09:22:56.691+0000] {processor.py:183} INFO - Processing /home/pkn/e-commerce_data_pipeline/dags/etl_dag.py took 0.040 seconds
[2024-02-16T09:23:26.944+0000] {processor.py:161} INFO - Started process (PID=382704) to work on /home/pkn/e-commerce_data_pipeline/dags/etl_dag.py
[2024-02-16T09:23:26.946+0000] {processor.py:830} INFO - Processing file /home/pkn/e-commerce_data_pipeline/dags/etl_dag.py for tasks to queue
[2024-02-16T09:23:26.947+0000] {logging_mixin.py:188} INFO - [2024-02-16T09:23:26.946+0000] {dagbag.py:538} INFO - Filling up the DagBag from /home/pkn/e-commerce_data_pipeline/dags/etl_dag.py
[2024-02-16T09:23:26.949+0000] {logging_mixin.py:188} INFO - [2024-02-16T09:23:26.949+0000] {dagbag.py:348} ERROR - Failed to import: /home/pkn/e-commerce_data_pipeline/dags/etl_dag.py
Traceback (most recent call last):
  File "/home/pkn/e-commerce_data_pipeline/venv/lib/python3.10/site-packages/airflow/models/dagbag.py", line 344, in parse
    loader.exec_module(new_module)
  File "<frozen importlib._bootstrap_external>", line 883, in exec_module
  File "<frozen importlib._bootstrap>", line 241, in _call_with_frames_removed
  File "/home/pkn/e-commerce_data_pipeline/dags/etl_dag.py", line 4, in <module>
    from ..scripts.imp_clean_trans_script import clean_transform_main
ImportError: attempted relative import with no known parent package
[2024-02-16T09:23:26.950+0000] {processor.py:842} WARNING - No viable dags retrieved from /home/pkn/e-commerce_data_pipeline/dags/etl_dag.py
[2024-02-16T09:23:26.994+0000] {processor.py:183} INFO - Processing /home/pkn/e-commerce_data_pipeline/dags/etl_dag.py took 0.055 seconds
[2024-02-16T09:23:57.901+0000] {processor.py:161} INFO - Started process (PID=383074) to work on /home/pkn/e-commerce_data_pipeline/dags/etl_dag.py
[2024-02-16T09:23:57.904+0000] {processor.py:830} INFO - Processing file /home/pkn/e-commerce_data_pipeline/dags/etl_dag.py for tasks to queue
[2024-02-16T09:23:57.905+0000] {logging_mixin.py:188} INFO - [2024-02-16T09:23:57.904+0000] {dagbag.py:538} INFO - Filling up the DagBag from /home/pkn/e-commerce_data_pipeline/dags/etl_dag.py
[2024-02-16T09:23:57.908+0000] {logging_mixin.py:188} INFO - [2024-02-16T09:23:57.907+0000] {dagbag.py:348} ERROR - Failed to import: /home/pkn/e-commerce_data_pipeline/dags/etl_dag.py
Traceback (most recent call last):
  File "/home/pkn/e-commerce_data_pipeline/venv/lib/python3.10/site-packages/airflow/models/dagbag.py", line 344, in parse
    loader.exec_module(new_module)
  File "<frozen importlib._bootstrap_external>", line 883, in exec_module
  File "<frozen importlib._bootstrap>", line 241, in _call_with_frames_removed
  File "/home/pkn/e-commerce_data_pipeline/dags/etl_dag.py", line 4, in <module>
    from ..scripts.imp_clean_trans_script import clean_transform_main
ImportError: attempted relative import with no known parent package
[2024-02-16T09:23:57.908+0000] {processor.py:842} WARNING - No viable dags retrieved from /home/pkn/e-commerce_data_pipeline/dags/etl_dag.py
[2024-02-16T09:23:57.939+0000] {processor.py:183} INFO - Processing /home/pkn/e-commerce_data_pipeline/dags/etl_dag.py took 0.043 seconds
[2024-02-16T09:24:28.647+0000] {processor.py:161} INFO - Started process (PID=383407) to work on /home/pkn/e-commerce_data_pipeline/dags/etl_dag.py
[2024-02-16T09:24:28.649+0000] {processor.py:830} INFO - Processing file /home/pkn/e-commerce_data_pipeline/dags/etl_dag.py for tasks to queue
[2024-02-16T09:24:28.650+0000] {logging_mixin.py:188} INFO - [2024-02-16T09:24:28.649+0000] {dagbag.py:538} INFO - Filling up the DagBag from /home/pkn/e-commerce_data_pipeline/dags/etl_dag.py
[2024-02-16T09:24:28.653+0000] {logging_mixin.py:188} INFO - [2024-02-16T09:24:28.652+0000] {dagbag.py:348} ERROR - Failed to import: /home/pkn/e-commerce_data_pipeline/dags/etl_dag.py
Traceback (most recent call last):
  File "/home/pkn/e-commerce_data_pipeline/venv/lib/python3.10/site-packages/airflow/models/dagbag.py", line 344, in parse
    loader.exec_module(new_module)
  File "<frozen importlib._bootstrap_external>", line 883, in exec_module
  File "<frozen importlib._bootstrap>", line 241, in _call_with_frames_removed
  File "/home/pkn/e-commerce_data_pipeline/dags/etl_dag.py", line 4, in <module>
    from ..scripts.imp_clean_trans_script import clean_transform_main
ImportError: attempted relative import with no known parent package
[2024-02-16T09:24:28.653+0000] {processor.py:842} WARNING - No viable dags retrieved from /home/pkn/e-commerce_data_pipeline/dags/etl_dag.py
[2024-02-16T09:24:28.687+0000] {processor.py:183} INFO - Processing /home/pkn/e-commerce_data_pipeline/dags/etl_dag.py took 0.046 seconds
[2024-02-16T09:24:40.375+0000] {processor.py:161} INFO - Started process (PID=383585) to work on /home/pkn/e-commerce_data_pipeline/dags/etl_dag.py
[2024-02-16T09:24:40.377+0000] {processor.py:830} INFO - Processing file /home/pkn/e-commerce_data_pipeline/dags/etl_dag.py for tasks to queue
[2024-02-16T09:24:40.378+0000] {logging_mixin.py:188} INFO - [2024-02-16T09:24:40.378+0000] {dagbag.py:538} INFO - Filling up the DagBag from /home/pkn/e-commerce_data_pipeline/dags/etl_dag.py
[2024-02-16T09:24:40.382+0000] {logging_mixin.py:188} INFO - [2024-02-16T09:24:40.381+0000] {dagbag.py:348} ERROR - Failed to import: /home/pkn/e-commerce_data_pipeline/dags/etl_dag.py
Traceback (most recent call last):
  File "/home/pkn/e-commerce_data_pipeline/venv/lib/python3.10/site-packages/airflow/models/dagbag.py", line 344, in parse
    loader.exec_module(new_module)
  File "<frozen importlib._bootstrap_external>", line 879, in exec_module
  File "<frozen importlib._bootstrap_external>", line 1017, in get_code
  File "<frozen importlib._bootstrap_external>", line 947, in source_to_code
  File "<frozen importlib._bootstrap>", line 241, in _call_with_frames_removed
  File "/home/pkn/e-commerce_data_pipeline/dags/etl_dag.py", line 4
    from e-commerce_data_pipeline.scripts.imp_clean_trans_script import clean_transform_main
          ^
SyntaxError: invalid syntax
[2024-02-16T09:24:40.382+0000] {processor.py:842} WARNING - No viable dags retrieved from /home/pkn/e-commerce_data_pipeline/dags/etl_dag.py
[2024-02-16T09:24:40.417+0000] {processor.py:183} INFO - Processing /home/pkn/e-commerce_data_pipeline/dags/etl_dag.py took 0.047 seconds
[2024-02-16T09:25:10.557+0000] {processor.py:161} INFO - Started process (PID=383835) to work on /home/pkn/e-commerce_data_pipeline/dags/etl_dag.py
[2024-02-16T09:25:10.559+0000] {processor.py:830} INFO - Processing file /home/pkn/e-commerce_data_pipeline/dags/etl_dag.py for tasks to queue
[2024-02-16T09:25:10.560+0000] {logging_mixin.py:188} INFO - [2024-02-16T09:25:10.559+0000] {dagbag.py:538} INFO - Filling up the DagBag from /home/pkn/e-commerce_data_pipeline/dags/etl_dag.py
[2024-02-16T09:25:10.563+0000] {logging_mixin.py:188} INFO - [2024-02-16T09:25:10.562+0000] {dagbag.py:348} ERROR - Failed to import: /home/pkn/e-commerce_data_pipeline/dags/etl_dag.py
Traceback (most recent call last):
  File "/home/pkn/e-commerce_data_pipeline/venv/lib/python3.10/site-packages/airflow/models/dagbag.py", line 344, in parse
    loader.exec_module(new_module)
  File "<frozen importlib._bootstrap_external>", line 879, in exec_module
  File "<frozen importlib._bootstrap_external>", line 1017, in get_code
  File "<frozen importlib._bootstrap_external>", line 947, in source_to_code
  File "<frozen importlib._bootstrap>", line 241, in _call_with_frames_removed
  File "/home/pkn/e-commerce_data_pipeline/dags/etl_dag.py", line 4
    from e-commerce_data_pipeline.scripts.imp_clean_trans_script import clean_transform_main
          ^
SyntaxError: invalid syntax
[2024-02-16T09:25:10.563+0000] {processor.py:842} WARNING - No viable dags retrieved from /home/pkn/e-commerce_data_pipeline/dags/etl_dag.py
[2024-02-16T09:25:10.597+0000] {processor.py:183} INFO - Processing /home/pkn/e-commerce_data_pipeline/dags/etl_dag.py took 0.046 seconds
[2024-02-16T09:25:41.050+0000] {processor.py:161} INFO - Started process (PID=384031) to work on /home/pkn/e-commerce_data_pipeline/dags/etl_dag.py
[2024-02-16T09:25:41.051+0000] {processor.py:830} INFO - Processing file /home/pkn/e-commerce_data_pipeline/dags/etl_dag.py for tasks to queue
[2024-02-16T09:25:41.052+0000] {logging_mixin.py:188} INFO - [2024-02-16T09:25:41.052+0000] {dagbag.py:538} INFO - Filling up the DagBag from /home/pkn/e-commerce_data_pipeline/dags/etl_dag.py
[2024-02-16T09:25:41.055+0000] {logging_mixin.py:188} INFO - [2024-02-16T09:25:41.055+0000] {dagbag.py:348} ERROR - Failed to import: /home/pkn/e-commerce_data_pipeline/dags/etl_dag.py
Traceback (most recent call last):
  File "/home/pkn/e-commerce_data_pipeline/venv/lib/python3.10/site-packages/airflow/models/dagbag.py", line 344, in parse
    loader.exec_module(new_module)
  File "<frozen importlib._bootstrap_external>", line 879, in exec_module
  File "<frozen importlib._bootstrap_external>", line 1017, in get_code
  File "<frozen importlib._bootstrap_external>", line 947, in source_to_code
  File "<frozen importlib._bootstrap>", line 241, in _call_with_frames_removed
  File "/home/pkn/e-commerce_data_pipeline/dags/etl_dag.py", line 4
    from e-commerce_data_pipeline.scripts.imp_clean_trans_script import clean_transform_main
          ^
SyntaxError: invalid syntax
[2024-02-16T09:25:41.056+0000] {processor.py:842} WARNING - No viable dags retrieved from /home/pkn/e-commerce_data_pipeline/dags/etl_dag.py
[2024-02-16T09:25:41.085+0000] {processor.py:183} INFO - Processing /home/pkn/e-commerce_data_pipeline/dags/etl_dag.py took 0.041 seconds
[2024-02-16T09:26:11.247+0000] {processor.py:161} INFO - Started process (PID=384253) to work on /home/pkn/e-commerce_data_pipeline/dags/etl_dag.py
[2024-02-16T09:26:11.251+0000] {processor.py:830} INFO - Processing file /home/pkn/e-commerce_data_pipeline/dags/etl_dag.py for tasks to queue
[2024-02-16T09:26:11.252+0000] {logging_mixin.py:188} INFO - [2024-02-16T09:26:11.252+0000] {dagbag.py:538} INFO - Filling up the DagBag from /home/pkn/e-commerce_data_pipeline/dags/etl_dag.py
[2024-02-16T09:26:11.255+0000] {logging_mixin.py:188} INFO - [2024-02-16T09:26:11.254+0000] {dagbag.py:348} ERROR - Failed to import: /home/pkn/e-commerce_data_pipeline/dags/etl_dag.py
Traceback (most recent call last):
  File "/home/pkn/e-commerce_data_pipeline/venv/lib/python3.10/site-packages/airflow/models/dagbag.py", line 344, in parse
    loader.exec_module(new_module)
  File "<frozen importlib._bootstrap_external>", line 879, in exec_module
  File "<frozen importlib._bootstrap_external>", line 1017, in get_code
  File "<frozen importlib._bootstrap_external>", line 947, in source_to_code
  File "<frozen importlib._bootstrap>", line 241, in _call_with_frames_removed
  File "/home/pkn/e-commerce_data_pipeline/dags/etl_dag.py", line 4
    from e-commerce_data_pipeline.scripts.imp_clean_trans_script import clean_transform_main
          ^
SyntaxError: invalid syntax
[2024-02-16T09:26:11.256+0000] {processor.py:842} WARNING - No viable dags retrieved from /home/pkn/e-commerce_data_pipeline/dags/etl_dag.py
[2024-02-16T09:26:11.297+0000] {processor.py:183} INFO - Processing /home/pkn/e-commerce_data_pipeline/dags/etl_dag.py took 0.055 seconds
[2024-02-16T09:26:42.150+0000] {processor.py:161} INFO - Started process (PID=384449) to work on /home/pkn/e-commerce_data_pipeline/dags/etl_dag.py
[2024-02-16T09:26:42.151+0000] {processor.py:830} INFO - Processing file /home/pkn/e-commerce_data_pipeline/dags/etl_dag.py for tasks to queue
[2024-02-16T09:26:42.152+0000] {logging_mixin.py:188} INFO - [2024-02-16T09:26:42.152+0000] {dagbag.py:538} INFO - Filling up the DagBag from /home/pkn/e-commerce_data_pipeline/dags/etl_dag.py
[2024-02-16T09:26:42.155+0000] {logging_mixin.py:188} INFO - [2024-02-16T09:26:42.154+0000] {dagbag.py:348} ERROR - Failed to import: /home/pkn/e-commerce_data_pipeline/dags/etl_dag.py
Traceback (most recent call last):
  File "/home/pkn/e-commerce_data_pipeline/venv/lib/python3.10/site-packages/airflow/models/dagbag.py", line 344, in parse
    loader.exec_module(new_module)
  File "<frozen importlib._bootstrap_external>", line 879, in exec_module
  File "<frozen importlib._bootstrap_external>", line 1017, in get_code
  File "<frozen importlib._bootstrap_external>", line 947, in source_to_code
  File "<frozen importlib._bootstrap>", line 241, in _call_with_frames_removed
  File "/home/pkn/e-commerce_data_pipeline/dags/etl_dag.py", line 4
    from e-commerce_data_pipeline.scripts.imp_clean_trans_script import clean_transform_main
          ^
SyntaxError: invalid syntax
[2024-02-16T09:26:42.155+0000] {processor.py:842} WARNING - No viable dags retrieved from /home/pkn/e-commerce_data_pipeline/dags/etl_dag.py
[2024-02-16T09:26:42.188+0000] {processor.py:183} INFO - Processing /home/pkn/e-commerce_data_pipeline/dags/etl_dag.py took 0.043 seconds
[2024-02-16T09:27:12.885+0000] {processor.py:161} INFO - Started process (PID=384645) to work on /home/pkn/e-commerce_data_pipeline/dags/etl_dag.py
[2024-02-16T09:27:12.887+0000] {processor.py:830} INFO - Processing file /home/pkn/e-commerce_data_pipeline/dags/etl_dag.py for tasks to queue
[2024-02-16T09:27:12.888+0000] {logging_mixin.py:188} INFO - [2024-02-16T09:27:12.888+0000] {dagbag.py:538} INFO - Filling up the DagBag from /home/pkn/e-commerce_data_pipeline/dags/etl_dag.py
[2024-02-16T09:27:12.891+0000] {logging_mixin.py:188} INFO - [2024-02-16T09:27:12.890+0000] {dagbag.py:348} ERROR - Failed to import: /home/pkn/e-commerce_data_pipeline/dags/etl_dag.py
Traceback (most recent call last):
  File "/home/pkn/e-commerce_data_pipeline/venv/lib/python3.10/site-packages/airflow/models/dagbag.py", line 344, in parse
    loader.exec_module(new_module)
  File "<frozen importlib._bootstrap_external>", line 879, in exec_module
  File "<frozen importlib._bootstrap_external>", line 1017, in get_code
  File "<frozen importlib._bootstrap_external>", line 947, in source_to_code
  File "<frozen importlib._bootstrap>", line 241, in _call_with_frames_removed
  File "/home/pkn/e-commerce_data_pipeline/dags/etl_dag.py", line 4
    from e-commerce_data_pipeline.scripts.imp_clean_trans_script import clean_transform_main
          ^
SyntaxError: invalid syntax
[2024-02-16T09:27:12.892+0000] {processor.py:842} WARNING - No viable dags retrieved from /home/pkn/e-commerce_data_pipeline/dags/etl_dag.py
[2024-02-16T09:27:12.927+0000] {processor.py:183} INFO - Processing /home/pkn/e-commerce_data_pipeline/dags/etl_dag.py took 0.046 seconds
[2024-02-16T09:27:43.212+0000] {processor.py:161} INFO - Started process (PID=384841) to work on /home/pkn/e-commerce_data_pipeline/dags/etl_dag.py
[2024-02-16T09:27:43.213+0000] {processor.py:830} INFO - Processing file /home/pkn/e-commerce_data_pipeline/dags/etl_dag.py for tasks to queue
[2024-02-16T09:27:43.214+0000] {logging_mixin.py:188} INFO - [2024-02-16T09:27:43.214+0000] {dagbag.py:538} INFO - Filling up the DagBag from /home/pkn/e-commerce_data_pipeline/dags/etl_dag.py
[2024-02-16T09:27:43.217+0000] {logging_mixin.py:188} INFO - [2024-02-16T09:27:43.216+0000] {dagbag.py:348} ERROR - Failed to import: /home/pkn/e-commerce_data_pipeline/dags/etl_dag.py
Traceback (most recent call last):
  File "/home/pkn/e-commerce_data_pipeline/venv/lib/python3.10/site-packages/airflow/models/dagbag.py", line 344, in parse
    loader.exec_module(new_module)
  File "<frozen importlib._bootstrap_external>", line 879, in exec_module
  File "<frozen importlib._bootstrap_external>", line 1017, in get_code
  File "<frozen importlib._bootstrap_external>", line 947, in source_to_code
  File "<frozen importlib._bootstrap>", line 241, in _call_with_frames_removed
  File "/home/pkn/e-commerce_data_pipeline/dags/etl_dag.py", line 4
    from e-commerce_data_pipeline.scripts.imp_clean_trans_script import clean_transform_main
          ^
SyntaxError: invalid syntax
[2024-02-16T09:27:43.217+0000] {processor.py:842} WARNING - No viable dags retrieved from /home/pkn/e-commerce_data_pipeline/dags/etl_dag.py
[2024-02-16T09:27:43.254+0000] {processor.py:183} INFO - Processing /home/pkn/e-commerce_data_pipeline/dags/etl_dag.py took 0.048 seconds
[2024-02-16T09:28:13.652+0000] {processor.py:161} INFO - Started process (PID=385086) to work on /home/pkn/e-commerce_data_pipeline/dags/etl_dag.py
[2024-02-16T09:28:13.653+0000] {processor.py:830} INFO - Processing file /home/pkn/e-commerce_data_pipeline/dags/etl_dag.py for tasks to queue
[2024-02-16T09:28:13.654+0000] {logging_mixin.py:188} INFO - [2024-02-16T09:28:13.654+0000] {dagbag.py:538} INFO - Filling up the DagBag from /home/pkn/e-commerce_data_pipeline/dags/etl_dag.py
[2024-02-16T09:28:13.657+0000] {logging_mixin.py:188} INFO - [2024-02-16T09:28:13.656+0000] {dagbag.py:348} ERROR - Failed to import: /home/pkn/e-commerce_data_pipeline/dags/etl_dag.py
Traceback (most recent call last):
  File "/home/pkn/e-commerce_data_pipeline/venv/lib/python3.10/site-packages/airflow/models/dagbag.py", line 344, in parse
    loader.exec_module(new_module)
  File "<frozen importlib._bootstrap_external>", line 879, in exec_module
  File "<frozen importlib._bootstrap_external>", line 1017, in get_code
  File "<frozen importlib._bootstrap_external>", line 947, in source_to_code
  File "<frozen importlib._bootstrap>", line 241, in _call_with_frames_removed
  File "/home/pkn/e-commerce_data_pipeline/dags/etl_dag.py", line 4
    from e-commerce_data_pipeline.scripts.imp_clean_trans_script import clean_transform_main
          ^
SyntaxError: invalid syntax
[2024-02-16T09:28:13.657+0000] {processor.py:842} WARNING - No viable dags retrieved from /home/pkn/e-commerce_data_pipeline/dags/etl_dag.py
[2024-02-16T09:28:13.688+0000] {processor.py:183} INFO - Processing /home/pkn/e-commerce_data_pipeline/dags/etl_dag.py took 0.042 seconds
[2024-02-16T09:28:44.368+0000] {processor.py:161} INFO - Started process (PID=385282) to work on /home/pkn/e-commerce_data_pipeline/dags/etl_dag.py
[2024-02-16T09:28:44.369+0000] {processor.py:830} INFO - Processing file /home/pkn/e-commerce_data_pipeline/dags/etl_dag.py for tasks to queue
[2024-02-16T09:28:44.370+0000] {logging_mixin.py:188} INFO - [2024-02-16T09:28:44.370+0000] {dagbag.py:538} INFO - Filling up the DagBag from /home/pkn/e-commerce_data_pipeline/dags/etl_dag.py
[2024-02-16T09:28:44.373+0000] {logging_mixin.py:188} INFO - [2024-02-16T09:28:44.372+0000] {dagbag.py:348} ERROR - Failed to import: /home/pkn/e-commerce_data_pipeline/dags/etl_dag.py
Traceback (most recent call last):
  File "/home/pkn/e-commerce_data_pipeline/venv/lib/python3.10/site-packages/airflow/models/dagbag.py", line 344, in parse
    loader.exec_module(new_module)
  File "<frozen importlib._bootstrap_external>", line 879, in exec_module
  File "<frozen importlib._bootstrap_external>", line 1017, in get_code
  File "<frozen importlib._bootstrap_external>", line 947, in source_to_code
  File "<frozen importlib._bootstrap>", line 241, in _call_with_frames_removed
  File "/home/pkn/e-commerce_data_pipeline/dags/etl_dag.py", line 4
    from e-commerce_data_pipeline.scripts.imp_clean_trans_script import clean_transform_main
          ^
SyntaxError: invalid syntax
[2024-02-16T09:28:44.373+0000] {processor.py:842} WARNING - No viable dags retrieved from /home/pkn/e-commerce_data_pipeline/dags/etl_dag.py
[2024-02-16T09:28:44.406+0000] {processor.py:183} INFO - Processing /home/pkn/e-commerce_data_pipeline/dags/etl_dag.py took 0.044 seconds
[2024-02-16T09:29:14.735+0000] {processor.py:161} INFO - Started process (PID=385523) to work on /home/pkn/e-commerce_data_pipeline/dags/etl_dag.py
[2024-02-16T09:29:14.737+0000] {processor.py:830} INFO - Processing file /home/pkn/e-commerce_data_pipeline/dags/etl_dag.py for tasks to queue
[2024-02-16T09:29:14.740+0000] {logging_mixin.py:188} INFO - [2024-02-16T09:29:14.739+0000] {dagbag.py:538} INFO - Filling up the DagBag from /home/pkn/e-commerce_data_pipeline/dags/etl_dag.py
[2024-02-16T09:29:14.744+0000] {logging_mixin.py:188} INFO - [2024-02-16T09:29:14.743+0000] {dagbag.py:348} ERROR - Failed to import: /home/pkn/e-commerce_data_pipeline/dags/etl_dag.py
Traceback (most recent call last):
  File "/home/pkn/e-commerce_data_pipeline/venv/lib/python3.10/site-packages/airflow/models/dagbag.py", line 344, in parse
    loader.exec_module(new_module)
  File "<frozen importlib._bootstrap_external>", line 879, in exec_module
  File "<frozen importlib._bootstrap_external>", line 1017, in get_code
  File "<frozen importlib._bootstrap_external>", line 947, in source_to_code
  File "<frozen importlib._bootstrap>", line 241, in _call_with_frames_removed
  File "/home/pkn/e-commerce_data_pipeline/dags/etl_dag.py", line 4
    from e-commerce_data_pipeline.scripts.imp_clean_trans_script import clean_transform_main
          ^
SyntaxError: invalid syntax
[2024-02-16T09:29:14.745+0000] {processor.py:842} WARNING - No viable dags retrieved from /home/pkn/e-commerce_data_pipeline/dags/etl_dag.py
[2024-02-16T09:29:14.776+0000] {processor.py:183} INFO - Processing /home/pkn/e-commerce_data_pipeline/dags/etl_dag.py took 0.046 seconds
[2024-02-16T09:29:44.805+0000] {processor.py:161} INFO - Started process (PID=385832) to work on /home/pkn/e-commerce_data_pipeline/dags/etl_dag.py
[2024-02-16T09:29:44.807+0000] {processor.py:830} INFO - Processing file /home/pkn/e-commerce_data_pipeline/dags/etl_dag.py for tasks to queue
[2024-02-16T09:29:44.808+0000] {logging_mixin.py:188} INFO - [2024-02-16T09:29:44.807+0000] {dagbag.py:538} INFO - Filling up the DagBag from /home/pkn/e-commerce_data_pipeline/dags/etl_dag.py
[2024-02-16T09:29:44.811+0000] {logging_mixin.py:188} INFO - [2024-02-16T09:29:44.810+0000] {dagbag.py:348} ERROR - Failed to import: /home/pkn/e-commerce_data_pipeline/dags/etl_dag.py
Traceback (most recent call last):
  File "/home/pkn/e-commerce_data_pipeline/venv/lib/python3.10/site-packages/airflow/models/dagbag.py", line 344, in parse
    loader.exec_module(new_module)
  File "<frozen importlib._bootstrap_external>", line 879, in exec_module
  File "<frozen importlib._bootstrap_external>", line 1017, in get_code
  File "<frozen importlib._bootstrap_external>", line 947, in source_to_code
  File "<frozen importlib._bootstrap>", line 241, in _call_with_frames_removed
  File "/home/pkn/e-commerce_data_pipeline/dags/etl_dag.py", line 4
    from e-commerce_data_pipeline.scripts.imp_clean_trans_script import clean_transform_main
          ^
SyntaxError: invalid syntax
[2024-02-16T09:29:44.811+0000] {processor.py:842} WARNING - No viable dags retrieved from /home/pkn/e-commerce_data_pipeline/dags/etl_dag.py
[2024-02-16T09:29:44.841+0000] {processor.py:183} INFO - Processing /home/pkn/e-commerce_data_pipeline/dags/etl_dag.py took 0.041 seconds
[2024-02-16T09:30:15.321+0000] {processor.py:161} INFO - Started process (PID=386028) to work on /home/pkn/e-commerce_data_pipeline/dags/etl_dag.py
[2024-02-16T09:30:15.323+0000] {processor.py:830} INFO - Processing file /home/pkn/e-commerce_data_pipeline/dags/etl_dag.py for tasks to queue
[2024-02-16T09:30:15.324+0000] {logging_mixin.py:188} INFO - [2024-02-16T09:30:15.323+0000] {dagbag.py:538} INFO - Filling up the DagBag from /home/pkn/e-commerce_data_pipeline/dags/etl_dag.py
[2024-02-16T09:30:15.327+0000] {logging_mixin.py:188} INFO - [2024-02-16T09:30:15.326+0000] {dagbag.py:348} ERROR - Failed to import: /home/pkn/e-commerce_data_pipeline/dags/etl_dag.py
Traceback (most recent call last):
  File "/home/pkn/e-commerce_data_pipeline/venv/lib/python3.10/site-packages/airflow/models/dagbag.py", line 344, in parse
    loader.exec_module(new_module)
  File "<frozen importlib._bootstrap_external>", line 879, in exec_module
  File "<frozen importlib._bootstrap_external>", line 1017, in get_code
  File "<frozen importlib._bootstrap_external>", line 947, in source_to_code
  File "<frozen importlib._bootstrap>", line 241, in _call_with_frames_removed
  File "/home/pkn/e-commerce_data_pipeline/dags/etl_dag.py", line 4
    from e-commerce_data_pipeline.scripts.imp_clean_trans_script import clean_transform_main
          ^
SyntaxError: invalid syntax
[2024-02-16T09:30:15.327+0000] {processor.py:842} WARNING - No viable dags retrieved from /home/pkn/e-commerce_data_pipeline/dags/etl_dag.py
[2024-02-16T09:30:15.361+0000] {processor.py:183} INFO - Processing /home/pkn/e-commerce_data_pipeline/dags/etl_dag.py took 0.046 seconds
[2024-02-16T09:30:46.219+0000] {processor.py:161} INFO - Started process (PID=386224) to work on /home/pkn/e-commerce_data_pipeline/dags/etl_dag.py
[2024-02-16T09:30:46.220+0000] {processor.py:830} INFO - Processing file /home/pkn/e-commerce_data_pipeline/dags/etl_dag.py for tasks to queue
[2024-02-16T09:30:46.220+0000] {logging_mixin.py:188} INFO - [2024-02-16T09:30:46.220+0000] {dagbag.py:538} INFO - Filling up the DagBag from /home/pkn/e-commerce_data_pipeline/dags/etl_dag.py
[2024-02-16T09:30:46.223+0000] {logging_mixin.py:188} INFO - [2024-02-16T09:30:46.222+0000] {dagbag.py:348} ERROR - Failed to import: /home/pkn/e-commerce_data_pipeline/dags/etl_dag.py
Traceback (most recent call last):
  File "/home/pkn/e-commerce_data_pipeline/venv/lib/python3.10/site-packages/airflow/models/dagbag.py", line 344, in parse
    loader.exec_module(new_module)
  File "<frozen importlib._bootstrap_external>", line 879, in exec_module
  File "<frozen importlib._bootstrap_external>", line 1017, in get_code
  File "<frozen importlib._bootstrap_external>", line 947, in source_to_code
  File "<frozen importlib._bootstrap>", line 241, in _call_with_frames_removed
  File "/home/pkn/e-commerce_data_pipeline/dags/etl_dag.py", line 4
    from e-commerce_data_pipeline.scripts.imp_clean_trans_script import clean_transform_main
          ^
SyntaxError: invalid syntax
[2024-02-16T09:30:46.223+0000] {processor.py:842} WARNING - No viable dags retrieved from /home/pkn/e-commerce_data_pipeline/dags/etl_dag.py
[2024-02-16T09:30:46.253+0000] {processor.py:183} INFO - Processing /home/pkn/e-commerce_data_pipeline/dags/etl_dag.py took 0.040 seconds
[2024-02-16T09:31:16.445+0000] {processor.py:161} INFO - Started process (PID=386447) to work on /home/pkn/e-commerce_data_pipeline/dags/etl_dag.py
[2024-02-16T09:31:16.447+0000] {processor.py:830} INFO - Processing file /home/pkn/e-commerce_data_pipeline/dags/etl_dag.py for tasks to queue
[2024-02-16T09:31:16.448+0000] {logging_mixin.py:188} INFO - [2024-02-16T09:31:16.448+0000] {dagbag.py:538} INFO - Filling up the DagBag from /home/pkn/e-commerce_data_pipeline/dags/etl_dag.py
[2024-02-16T09:31:16.451+0000] {logging_mixin.py:188} INFO - [2024-02-16T09:31:16.451+0000] {dagbag.py:348} ERROR - Failed to import: /home/pkn/e-commerce_data_pipeline/dags/etl_dag.py
Traceback (most recent call last):
  File "/home/pkn/e-commerce_data_pipeline/venv/lib/python3.10/site-packages/airflow/models/dagbag.py", line 344, in parse
    loader.exec_module(new_module)
  File "<frozen importlib._bootstrap_external>", line 879, in exec_module
  File "<frozen importlib._bootstrap_external>", line 1017, in get_code
  File "<frozen importlib._bootstrap_external>", line 947, in source_to_code
  File "<frozen importlib._bootstrap>", line 241, in _call_with_frames_removed
  File "/home/pkn/e-commerce_data_pipeline/dags/etl_dag.py", line 4
    from e-commerce_data_pipeline.scripts.imp_clean_trans_script import clean_transform_main
          ^
SyntaxError: invalid syntax
[2024-02-16T09:31:16.452+0000] {processor.py:842} WARNING - No viable dags retrieved from /home/pkn/e-commerce_data_pipeline/dags/etl_dag.py
[2024-02-16T09:31:16.487+0000] {processor.py:183} INFO - Processing /home/pkn/e-commerce_data_pipeline/dags/etl_dag.py took 0.047 seconds
[2024-02-16T09:31:46.886+0000] {processor.py:161} INFO - Started process (PID=386642) to work on /home/pkn/e-commerce_data_pipeline/dags/etl_dag.py
[2024-02-16T09:31:46.888+0000] {processor.py:830} INFO - Processing file /home/pkn/e-commerce_data_pipeline/dags/etl_dag.py for tasks to queue
[2024-02-16T09:31:46.889+0000] {logging_mixin.py:188} INFO - [2024-02-16T09:31:46.889+0000] {dagbag.py:538} INFO - Filling up the DagBag from /home/pkn/e-commerce_data_pipeline/dags/etl_dag.py
[2024-02-16T09:31:46.892+0000] {logging_mixin.py:188} INFO - [2024-02-16T09:31:46.891+0000] {dagbag.py:348} ERROR - Failed to import: /home/pkn/e-commerce_data_pipeline/dags/etl_dag.py
Traceback (most recent call last):
  File "/home/pkn/e-commerce_data_pipeline/venv/lib/python3.10/site-packages/airflow/models/dagbag.py", line 344, in parse
    loader.exec_module(new_module)
  File "<frozen importlib._bootstrap_external>", line 879, in exec_module
  File "<frozen importlib._bootstrap_external>", line 1017, in get_code
  File "<frozen importlib._bootstrap_external>", line 947, in source_to_code
  File "<frozen importlib._bootstrap>", line 241, in _call_with_frames_removed
  File "/home/pkn/e-commerce_data_pipeline/dags/etl_dag.py", line 4
    from e-commerce_data_pipeline.scripts.imp_clean_trans_script import clean_transform_main
          ^
SyntaxError: invalid syntax
[2024-02-16T09:31:46.892+0000] {processor.py:842} WARNING - No viable dags retrieved from /home/pkn/e-commerce_data_pipeline/dags/etl_dag.py
[2024-02-16T09:31:46.929+0000] {processor.py:183} INFO - Processing /home/pkn/e-commerce_data_pipeline/dags/etl_dag.py took 0.048 seconds
[2024-02-16T09:32:17.150+0000] {processor.py:161} INFO - Started process (PID=386838) to work on /home/pkn/e-commerce_data_pipeline/dags/etl_dag.py
[2024-02-16T09:32:17.151+0000] {processor.py:830} INFO - Processing file /home/pkn/e-commerce_data_pipeline/dags/etl_dag.py for tasks to queue
[2024-02-16T09:32:17.152+0000] {logging_mixin.py:188} INFO - [2024-02-16T09:32:17.151+0000] {dagbag.py:538} INFO - Filling up the DagBag from /home/pkn/e-commerce_data_pipeline/dags/etl_dag.py
[2024-02-16T09:32:17.155+0000] {logging_mixin.py:188} INFO - [2024-02-16T09:32:17.154+0000] {dagbag.py:348} ERROR - Failed to import: /home/pkn/e-commerce_data_pipeline/dags/etl_dag.py
Traceback (most recent call last):
  File "/home/pkn/e-commerce_data_pipeline/venv/lib/python3.10/site-packages/airflow/models/dagbag.py", line 344, in parse
    loader.exec_module(new_module)
  File "<frozen importlib._bootstrap_external>", line 879, in exec_module
  File "<frozen importlib._bootstrap_external>", line 1017, in get_code
  File "<frozen importlib._bootstrap_external>", line 947, in source_to_code
  File "<frozen importlib._bootstrap>", line 241, in _call_with_frames_removed
  File "/home/pkn/e-commerce_data_pipeline/dags/etl_dag.py", line 4
    from e-commerce_data_pipeline.scripts.imp_clean_trans_script import clean_transform_main
          ^
SyntaxError: invalid syntax
[2024-02-16T09:32:17.155+0000] {processor.py:842} WARNING - No viable dags retrieved from /home/pkn/e-commerce_data_pipeline/dags/etl_dag.py
[2024-02-16T09:32:17.183+0000] {processor.py:183} INFO - Processing /home/pkn/e-commerce_data_pipeline/dags/etl_dag.py took 0.037 seconds
[2024-02-16T09:32:47.500+0000] {processor.py:161} INFO - Started process (PID=387126) to work on /home/pkn/e-commerce_data_pipeline/dags/etl_dag.py
[2024-02-16T09:32:47.501+0000] {processor.py:830} INFO - Processing file /home/pkn/e-commerce_data_pipeline/dags/etl_dag.py for tasks to queue
[2024-02-16T09:32:47.502+0000] {logging_mixin.py:188} INFO - [2024-02-16T09:32:47.502+0000] {dagbag.py:538} INFO - Filling up the DagBag from /home/pkn/e-commerce_data_pipeline/dags/etl_dag.py
[2024-02-16T09:32:47.505+0000] {logging_mixin.py:188} INFO - [2024-02-16T09:32:47.504+0000] {dagbag.py:348} ERROR - Failed to import: /home/pkn/e-commerce_data_pipeline/dags/etl_dag.py
Traceback (most recent call last):
  File "/home/pkn/e-commerce_data_pipeline/venv/lib/python3.10/site-packages/airflow/models/dagbag.py", line 344, in parse
    loader.exec_module(new_module)
  File "<frozen importlib._bootstrap_external>", line 879, in exec_module
  File "<frozen importlib._bootstrap_external>", line 1017, in get_code
  File "<frozen importlib._bootstrap_external>", line 947, in source_to_code
  File "<frozen importlib._bootstrap>", line 241, in _call_with_frames_removed
  File "/home/pkn/e-commerce_data_pipeline/dags/etl_dag.py", line 4
    from e-commerce_data_pipeline.scripts.imp_clean_trans_script import clean_transform_main
          ^
SyntaxError: invalid syntax
[2024-02-16T09:32:47.506+0000] {processor.py:842} WARNING - No viable dags retrieved from /home/pkn/e-commerce_data_pipeline/dags/etl_dag.py
[2024-02-16T09:32:47.541+0000] {processor.py:183} INFO - Processing /home/pkn/e-commerce_data_pipeline/dags/etl_dag.py took 0.047 seconds
[2024-02-16T09:33:17.874+0000] {processor.py:161} INFO - Started process (PID=387322) to work on /home/pkn/e-commerce_data_pipeline/dags/etl_dag.py
[2024-02-16T09:33:17.875+0000] {processor.py:830} INFO - Processing file /home/pkn/e-commerce_data_pipeline/dags/etl_dag.py for tasks to queue
[2024-02-16T09:33:17.876+0000] {logging_mixin.py:188} INFO - [2024-02-16T09:33:17.876+0000] {dagbag.py:538} INFO - Filling up the DagBag from /home/pkn/e-commerce_data_pipeline/dags/etl_dag.py
[2024-02-16T09:33:17.879+0000] {logging_mixin.py:188} INFO - [2024-02-16T09:33:17.879+0000] {dagbag.py:348} ERROR - Failed to import: /home/pkn/e-commerce_data_pipeline/dags/etl_dag.py
Traceback (most recent call last):
  File "/home/pkn/e-commerce_data_pipeline/venv/lib/python3.10/site-packages/airflow/models/dagbag.py", line 344, in parse
    loader.exec_module(new_module)
  File "<frozen importlib._bootstrap_external>", line 879, in exec_module
  File "<frozen importlib._bootstrap_external>", line 1017, in get_code
  File "<frozen importlib._bootstrap_external>", line 947, in source_to_code
  File "<frozen importlib._bootstrap>", line 241, in _call_with_frames_removed
  File "/home/pkn/e-commerce_data_pipeline/dags/etl_dag.py", line 4
    from e-commerce_data_pipeline.scripts.imp_clean_trans_script import clean_transform_main
          ^
SyntaxError: invalid syntax
[2024-02-16T09:33:17.880+0000] {processor.py:842} WARNING - No viable dags retrieved from /home/pkn/e-commerce_data_pipeline/dags/etl_dag.py
[2024-02-16T09:33:17.912+0000] {processor.py:183} INFO - Processing /home/pkn/e-commerce_data_pipeline/dags/etl_dag.py took 0.044 seconds
[2024-02-16T09:33:48.062+0000] {processor.py:161} INFO - Started process (PID=387515) to work on /home/pkn/e-commerce_data_pipeline/dags/etl_dag.py
[2024-02-16T09:33:48.063+0000] {processor.py:830} INFO - Processing file /home/pkn/e-commerce_data_pipeline/dags/etl_dag.py for tasks to queue
[2024-02-16T09:33:48.064+0000] {logging_mixin.py:188} INFO - [2024-02-16T09:33:48.064+0000] {dagbag.py:538} INFO - Filling up the DagBag from /home/pkn/e-commerce_data_pipeline/dags/etl_dag.py
[2024-02-16T09:33:48.067+0000] {logging_mixin.py:188} INFO - [2024-02-16T09:33:48.066+0000] {dagbag.py:348} ERROR - Failed to import: /home/pkn/e-commerce_data_pipeline/dags/etl_dag.py
Traceback (most recent call last):
  File "/home/pkn/e-commerce_data_pipeline/venv/lib/python3.10/site-packages/airflow/models/dagbag.py", line 344, in parse
    loader.exec_module(new_module)
  File "<frozen importlib._bootstrap_external>", line 879, in exec_module
  File "<frozen importlib._bootstrap_external>", line 1017, in get_code
  File "<frozen importlib._bootstrap_external>", line 947, in source_to_code
  File "<frozen importlib._bootstrap>", line 241, in _call_with_frames_removed
  File "/home/pkn/e-commerce_data_pipeline/dags/etl_dag.py", line 4
    from e-commerce_data_pipeline.scripts.imp_clean_trans_script import clean_transform_main
          ^
SyntaxError: invalid syntax
[2024-02-16T09:33:48.068+0000] {processor.py:842} WARNING - No viable dags retrieved from /home/pkn/e-commerce_data_pipeline/dags/etl_dag.py
[2024-02-16T09:33:48.101+0000] {processor.py:183} INFO - Processing /home/pkn/e-commerce_data_pipeline/dags/etl_dag.py took 0.045 seconds
[2024-02-16T09:34:18.340+0000] {processor.py:161} INFO - Started process (PID=387711) to work on /home/pkn/e-commerce_data_pipeline/dags/etl_dag.py
[2024-02-16T09:34:18.342+0000] {processor.py:830} INFO - Processing file /home/pkn/e-commerce_data_pipeline/dags/etl_dag.py for tasks to queue
[2024-02-16T09:34:18.343+0000] {logging_mixin.py:188} INFO - [2024-02-16T09:34:18.342+0000] {dagbag.py:538} INFO - Filling up the DagBag from /home/pkn/e-commerce_data_pipeline/dags/etl_dag.py
[2024-02-16T09:34:18.345+0000] {logging_mixin.py:188} INFO - [2024-02-16T09:34:18.344+0000] {dagbag.py:348} ERROR - Failed to import: /home/pkn/e-commerce_data_pipeline/dags/etl_dag.py
Traceback (most recent call last):
  File "/home/pkn/e-commerce_data_pipeline/venv/lib/python3.10/site-packages/airflow/models/dagbag.py", line 344, in parse
    loader.exec_module(new_module)
  File "<frozen importlib._bootstrap_external>", line 879, in exec_module
  File "<frozen importlib._bootstrap_external>", line 1017, in get_code
  File "<frozen importlib._bootstrap_external>", line 947, in source_to_code
  File "<frozen importlib._bootstrap>", line 241, in _call_with_frames_removed
  File "/home/pkn/e-commerce_data_pipeline/dags/etl_dag.py", line 4
    from e-commerce_data_pipeline.scripts.imp_clean_trans_script import clean_transform_main
          ^
SyntaxError: invalid syntax
[2024-02-16T09:34:18.345+0000] {processor.py:842} WARNING - No viable dags retrieved from /home/pkn/e-commerce_data_pipeline/dags/etl_dag.py
[2024-02-16T09:34:18.381+0000] {processor.py:183} INFO - Processing /home/pkn/e-commerce_data_pipeline/dags/etl_dag.py took 0.046 seconds
[2024-02-16T09:34:48.630+0000] {processor.py:161} INFO - Started process (PID=387906) to work on /home/pkn/e-commerce_data_pipeline/dags/etl_dag.py
[2024-02-16T09:34:48.632+0000] {processor.py:830} INFO - Processing file /home/pkn/e-commerce_data_pipeline/dags/etl_dag.py for tasks to queue
[2024-02-16T09:34:48.633+0000] {logging_mixin.py:188} INFO - [2024-02-16T09:34:48.633+0000] {dagbag.py:538} INFO - Filling up the DagBag from /home/pkn/e-commerce_data_pipeline/dags/etl_dag.py
[2024-02-16T09:34:48.637+0000] {logging_mixin.py:188} INFO - [2024-02-16T09:34:48.636+0000] {dagbag.py:348} ERROR - Failed to import: /home/pkn/e-commerce_data_pipeline/dags/etl_dag.py
Traceback (most recent call last):
  File "/home/pkn/e-commerce_data_pipeline/venv/lib/python3.10/site-packages/airflow/models/dagbag.py", line 344, in parse
    loader.exec_module(new_module)
  File "<frozen importlib._bootstrap_external>", line 879, in exec_module
  File "<frozen importlib._bootstrap_external>", line 1017, in get_code
  File "<frozen importlib._bootstrap_external>", line 947, in source_to_code
  File "<frozen importlib._bootstrap>", line 241, in _call_with_frames_removed
  File "/home/pkn/e-commerce_data_pipeline/dags/etl_dag.py", line 4
    from e-commerce_data_pipeline.scripts.imp_clean_trans_script import clean_transform_main
          ^
SyntaxError: invalid syntax
[2024-02-16T09:34:48.637+0000] {processor.py:842} WARNING - No viable dags retrieved from /home/pkn/e-commerce_data_pipeline/dags/etl_dag.py
[2024-02-16T09:34:48.670+0000] {processor.py:183} INFO - Processing /home/pkn/e-commerce_data_pipeline/dags/etl_dag.py took 0.050 seconds
[2024-02-16T09:35:18.716+0000] {processor.py:161} INFO - Started process (PID=388132) to work on /home/pkn/e-commerce_data_pipeline/dags/etl_dag.py
[2024-02-16T09:35:18.717+0000] {processor.py:830} INFO - Processing file /home/pkn/e-commerce_data_pipeline/dags/etl_dag.py for tasks to queue
[2024-02-16T09:35:18.718+0000] {logging_mixin.py:188} INFO - [2024-02-16T09:35:18.718+0000] {dagbag.py:538} INFO - Filling up the DagBag from /home/pkn/e-commerce_data_pipeline/dags/etl_dag.py
[2024-02-16T09:35:18.721+0000] {logging_mixin.py:188} INFO - [2024-02-16T09:35:18.721+0000] {dagbag.py:348} ERROR - Failed to import: /home/pkn/e-commerce_data_pipeline/dags/etl_dag.py
Traceback (most recent call last):
  File "/home/pkn/e-commerce_data_pipeline/venv/lib/python3.10/site-packages/airflow/models/dagbag.py", line 344, in parse
    loader.exec_module(new_module)
  File "<frozen importlib._bootstrap_external>", line 879, in exec_module
  File "<frozen importlib._bootstrap_external>", line 1017, in get_code
  File "<frozen importlib._bootstrap_external>", line 947, in source_to_code
  File "<frozen importlib._bootstrap>", line 241, in _call_with_frames_removed
  File "/home/pkn/e-commerce_data_pipeline/dags/etl_dag.py", line 4
    from e-commerce_data_pipeline.scripts.imp_clean_trans_script import clean_transform_main
          ^
SyntaxError: invalid syntax
[2024-02-16T09:35:18.722+0000] {processor.py:842} WARNING - No viable dags retrieved from /home/pkn/e-commerce_data_pipeline/dags/etl_dag.py
[2024-02-16T09:35:18.756+0000] {processor.py:183} INFO - Processing /home/pkn/e-commerce_data_pipeline/dags/etl_dag.py took 0.046 seconds
[2024-02-16T09:35:49.458+0000] {processor.py:161} INFO - Started process (PID=388327) to work on /home/pkn/e-commerce_data_pipeline/dags/etl_dag.py
[2024-02-16T09:35:49.459+0000] {processor.py:830} INFO - Processing file /home/pkn/e-commerce_data_pipeline/dags/etl_dag.py for tasks to queue
[2024-02-16T09:35:49.461+0000] {logging_mixin.py:188} INFO - [2024-02-16T09:35:49.460+0000] {dagbag.py:538} INFO - Filling up the DagBag from /home/pkn/e-commerce_data_pipeline/dags/etl_dag.py
[2024-02-16T09:35:49.464+0000] {logging_mixin.py:188} INFO - [2024-02-16T09:35:49.463+0000] {dagbag.py:348} ERROR - Failed to import: /home/pkn/e-commerce_data_pipeline/dags/etl_dag.py
Traceback (most recent call last):
  File "/home/pkn/e-commerce_data_pipeline/venv/lib/python3.10/site-packages/airflow/models/dagbag.py", line 344, in parse
    loader.exec_module(new_module)
  File "<frozen importlib._bootstrap_external>", line 879, in exec_module
  File "<frozen importlib._bootstrap_external>", line 1017, in get_code
  File "<frozen importlib._bootstrap_external>", line 947, in source_to_code
  File "<frozen importlib._bootstrap>", line 241, in _call_with_frames_removed
  File "/home/pkn/e-commerce_data_pipeline/dags/etl_dag.py", line 4
    from e-commerce_data_pipeline.scripts.imp_clean_trans_script import clean_transform_main
          ^
SyntaxError: invalid syntax
[2024-02-16T09:35:49.464+0000] {processor.py:842} WARNING - No viable dags retrieved from /home/pkn/e-commerce_data_pipeline/dags/etl_dag.py
[2024-02-16T09:35:49.497+0000] {processor.py:183} INFO - Processing /home/pkn/e-commerce_data_pipeline/dags/etl_dag.py took 0.044 seconds
[2024-02-16T09:36:19.575+0000] {processor.py:161} INFO - Started process (PID=388550) to work on /home/pkn/e-commerce_data_pipeline/dags/etl_dag.py
[2024-02-16T09:36:19.579+0000] {processor.py:830} INFO - Processing file /home/pkn/e-commerce_data_pipeline/dags/etl_dag.py for tasks to queue
[2024-02-16T09:36:19.580+0000] {logging_mixin.py:188} INFO - [2024-02-16T09:36:19.580+0000] {dagbag.py:538} INFO - Filling up the DagBag from /home/pkn/e-commerce_data_pipeline/dags/etl_dag.py
[2024-02-16T09:36:19.584+0000] {logging_mixin.py:188} INFO - [2024-02-16T09:36:19.583+0000] {dagbag.py:348} ERROR - Failed to import: /home/pkn/e-commerce_data_pipeline/dags/etl_dag.py
Traceback (most recent call last):
  File "/home/pkn/e-commerce_data_pipeline/venv/lib/python3.10/site-packages/airflow/models/dagbag.py", line 344, in parse
    loader.exec_module(new_module)
  File "<frozen importlib._bootstrap_external>", line 879, in exec_module
  File "<frozen importlib._bootstrap_external>", line 1017, in get_code
  File "<frozen importlib._bootstrap_external>", line 947, in source_to_code
  File "<frozen importlib._bootstrap>", line 241, in _call_with_frames_removed
  File "/home/pkn/e-commerce_data_pipeline/dags/etl_dag.py", line 4
    from e-commerce_data_pipeline.scripts.imp_clean_trans_script import clean_transform_main
          ^
SyntaxError: invalid syntax
[2024-02-16T09:36:19.584+0000] {processor.py:842} WARNING - No viable dags retrieved from /home/pkn/e-commerce_data_pipeline/dags/etl_dag.py
[2024-02-16T09:36:19.628+0000] {processor.py:183} INFO - Processing /home/pkn/e-commerce_data_pipeline/dags/etl_dag.py took 0.060 seconds
[2024-02-16T09:36:49.795+0000] {processor.py:161} INFO - Started process (PID=388923) to work on /home/pkn/e-commerce_data_pipeline/dags/etl_dag.py
[2024-02-16T09:36:49.796+0000] {processor.py:830} INFO - Processing file /home/pkn/e-commerce_data_pipeline/dags/etl_dag.py for tasks to queue
[2024-02-16T09:36:49.797+0000] {logging_mixin.py:188} INFO - [2024-02-16T09:36:49.797+0000] {dagbag.py:538} INFO - Filling up the DagBag from /home/pkn/e-commerce_data_pipeline/dags/etl_dag.py
[2024-02-16T09:36:49.801+0000] {logging_mixin.py:188} INFO - [2024-02-16T09:36:49.800+0000] {dagbag.py:348} ERROR - Failed to import: /home/pkn/e-commerce_data_pipeline/dags/etl_dag.py
Traceback (most recent call last):
  File "/home/pkn/e-commerce_data_pipeline/venv/lib/python3.10/site-packages/airflow/models/dagbag.py", line 344, in parse
    loader.exec_module(new_module)
  File "<frozen importlib._bootstrap_external>", line 879, in exec_module
  File "<frozen importlib._bootstrap_external>", line 1017, in get_code
  File "<frozen importlib._bootstrap_external>", line 947, in source_to_code
  File "<frozen importlib._bootstrap>", line 241, in _call_with_frames_removed
  File "/home/pkn/e-commerce_data_pipeline/dags/etl_dag.py", line 4
    from e-commerce_data_pipeline.scripts.imp_clean_trans_script import clean_transform_main
          ^
SyntaxError: invalid syntax
[2024-02-16T09:36:49.801+0000] {processor.py:842} WARNING - No viable dags retrieved from /home/pkn/e-commerce_data_pipeline/dags/etl_dag.py
[2024-02-16T09:36:49.836+0000] {processor.py:183} INFO - Processing /home/pkn/e-commerce_data_pipeline/dags/etl_dag.py took 0.047 seconds
[2024-02-16T09:37:19.931+0000] {processor.py:161} INFO - Started process (PID=389313) to work on /home/pkn/e-commerce_data_pipeline/dags/etl_dag.py
[2024-02-16T09:37:19.934+0000] {processor.py:830} INFO - Processing file /home/pkn/e-commerce_data_pipeline/dags/etl_dag.py for tasks to queue
[2024-02-16T09:37:19.935+0000] {logging_mixin.py:188} INFO - [2024-02-16T09:37:19.934+0000] {dagbag.py:538} INFO - Filling up the DagBag from /home/pkn/e-commerce_data_pipeline/dags/etl_dag.py
[2024-02-16T09:37:19.938+0000] {logging_mixin.py:188} INFO - [2024-02-16T09:37:19.937+0000] {dagbag.py:348} ERROR - Failed to import: /home/pkn/e-commerce_data_pipeline/dags/etl_dag.py
Traceback (most recent call last):
  File "/home/pkn/e-commerce_data_pipeline/venv/lib/python3.10/site-packages/airflow/models/dagbag.py", line 344, in parse
    loader.exec_module(new_module)
  File "<frozen importlib._bootstrap_external>", line 879, in exec_module
  File "<frozen importlib._bootstrap_external>", line 1017, in get_code
  File "<frozen importlib._bootstrap_external>", line 947, in source_to_code
  File "<frozen importlib._bootstrap>", line 241, in _call_with_frames_removed
  File "/home/pkn/e-commerce_data_pipeline/dags/etl_dag.py", line 4
    from e-commerce_data_pipeline.scripts.imp_clean_trans_script import clean_transform_main
          ^
SyntaxError: invalid syntax
[2024-02-16T09:37:19.938+0000] {processor.py:842} WARNING - No viable dags retrieved from /home/pkn/e-commerce_data_pipeline/dags/etl_dag.py
[2024-02-16T09:37:19.973+0000] {processor.py:183} INFO - Processing /home/pkn/e-commerce_data_pipeline/dags/etl_dag.py took 0.046 seconds
[2024-02-16T09:37:50.137+0000] {processor.py:161} INFO - Started process (PID=389629) to work on /home/pkn/e-commerce_data_pipeline/dags/etl_dag.py
[2024-02-16T09:37:50.138+0000] {processor.py:830} INFO - Processing file /home/pkn/e-commerce_data_pipeline/dags/etl_dag.py for tasks to queue
[2024-02-16T09:37:50.139+0000] {logging_mixin.py:188} INFO - [2024-02-16T09:37:50.139+0000] {dagbag.py:538} INFO - Filling up the DagBag from /home/pkn/e-commerce_data_pipeline/dags/etl_dag.py
[2024-02-16T09:37:50.142+0000] {logging_mixin.py:188} INFO - [2024-02-16T09:37:50.141+0000] {dagbag.py:348} ERROR - Failed to import: /home/pkn/e-commerce_data_pipeline/dags/etl_dag.py
Traceback (most recent call last):
  File "/home/pkn/e-commerce_data_pipeline/venv/lib/python3.10/site-packages/airflow/models/dagbag.py", line 344, in parse
    loader.exec_module(new_module)
  File "<frozen importlib._bootstrap_external>", line 879, in exec_module
  File "<frozen importlib._bootstrap_external>", line 1017, in get_code
  File "<frozen importlib._bootstrap_external>", line 947, in source_to_code
  File "<frozen importlib._bootstrap>", line 241, in _call_with_frames_removed
  File "/home/pkn/e-commerce_data_pipeline/dags/etl_dag.py", line 4
    from e-commerce_data_pipeline.scripts.imp_clean_trans_script import clean_transform_main
          ^
SyntaxError: invalid syntax
[2024-02-16T09:37:50.143+0000] {processor.py:842} WARNING - No viable dags retrieved from /home/pkn/e-commerce_data_pipeline/dags/etl_dag.py
[2024-02-16T09:37:50.169+0000] {processor.py:183} INFO - Processing /home/pkn/e-commerce_data_pipeline/dags/etl_dag.py took 0.036 seconds
